2021-08-13 17:06:52,037 - util.py[DEBUG]: Cloud-init v. 21.1-19-gbad84ad4-0ubuntu1~20.04.2 running 'init-local' at Fri, 13 Aug 2021 17:06:51 +0000. Up 7.21 seconds.
2021-08-13 17:06:52,037 - main.py[DEBUG]: No kernel command line url found.
2021-08-13 17:06:52,038 - main.py[DEBUG]: Closing stdin.
2021-08-13 17:06:52,040 - util.py[DEBUG]: Writing to /var/log/cloud-init.log - ab: [644] 0 bytes
2021-08-13 17:06:52,041 - util.py[DEBUG]: Changing the ownership of /var/log/cloud-init.log to 104:4
2021-08-13 17:06:52,041 - util.py[DEBUG]: Attempting to remove /var/lib/cloud/instance/boot-finished
2021-08-13 17:06:52,041 - util.py[DEBUG]: Attempting to remove /var/lib/cloud/data/no-net
2021-08-13 17:06:52,046 - handlers.py[DEBUG]: start: init-local/check-cache: attempting to read from cache [check]
2021-08-13 17:06:52,046 - util.py[DEBUG]: Reading from /var/lib/cloud/instance/obj.pkl (quiet=False)
2021-08-13 17:06:52,046 - stages.py[DEBUG]: no cache found
2021-08-13 17:06:52,046 - handlers.py[DEBUG]: finish: init-local/check-cache: SUCCESS: no cache found
2021-08-13 17:06:52,046 - util.py[DEBUG]: Attempting to remove /var/lib/cloud/instance
2021-08-13 17:06:52,050 - stages.py[DEBUG]: Using distro class <class 'cloudinit.distros.ubuntu.Distro'>
2021-08-13 17:06:52,050 - __init__.py[DEBUG]: Looking for data source in: ['Ec2', 'None'], via packages ['', 'cloudinit.sources'] that matches dependencies ['FILESYSTEM']
2021-08-13 17:06:52,066 - __init__.py[DEBUG]: Searching for local data source in: ['DataSourceEc2Local']
2021-08-13 17:06:52,066 - handlers.py[DEBUG]: start: init-local/search-Ec2Local: searching for local data from DataSourceEc2Local
2021-08-13 17:06:52,066 - __init__.py[DEBUG]: Seeing if we can get any data from <class 'cloudinit.sources.DataSourceEc2.DataSourceEc2Local'>
2021-08-13 17:06:52,066 - __init__.py[DEBUG]: Update datasource metadata and network config due to events: New instance first boot
2021-08-13 17:06:52,066 - util.py[DEBUG]: Reading from /sys/hypervisor/uuid (quiet=False)
2021-08-13 17:06:52,066 - util.py[DEBUG]: Read 37 bytes from /sys/hypervisor/uuid
2021-08-13 17:06:52,066 - dmi.py[DEBUG]: querying dmi data /sys/class/dmi/id/product_serial
2021-08-13 17:06:52,066 - dmi.py[DEBUG]: querying dmi data /sys/class/dmi/id/chassis_asset_tag
2021-08-13 17:06:52,066 - dmi.py[DEBUG]: querying dmi data /sys/class/dmi/id/sys_vendor
2021-08-13 17:06:52,066 - DataSourceEc2.py[DEBUG]: strict_mode: warn, cloud_name=aws cloud_platform=ec2
2021-08-13 17:06:52,067 - util.py[DEBUG]: Reading from /sys/class/net/eth0/name_assign_type (quiet=False)
2021-08-13 17:06:52,067 - __init__.py[DEBUG]: Found unstable nic names: ['eth0']; calling udevadm settle
2021-08-13 17:06:52,067 - subp.py[DEBUG]: Running command ['udevadm', 'settle'] with allowed return codes [0] (shell=False, capture=True)
2021-08-13 17:06:52,090 - util.py[DEBUG]: Waiting for udev events to settle took 0.023 seconds
2021-08-13 17:06:52,090 - util.py[DEBUG]: Reading from /sys/class/net/eth0/carrier (quiet=False)
2021-08-13 17:06:52,091 - util.py[DEBUG]: Reading from /sys/class/net/eth0/dormant (quiet=False)
2021-08-13 17:06:52,091 - util.py[DEBUG]: Reading from /sys/class/net/eth0/operstate (quiet=False)
2021-08-13 17:06:52,091 - util.py[DEBUG]: Read 5 bytes from /sys/class/net/eth0/operstate
2021-08-13 17:06:52,091 - util.py[DEBUG]: Reading from /sys/class/net/eth0/address (quiet=False)
2021-08-13 17:06:52,091 - util.py[DEBUG]: Read 18 bytes from /sys/class/net/eth0/address
2021-08-13 17:06:52,091 - dhcp.py[DEBUG]: Performing a dhcp discovery on eth0
2021-08-13 17:06:52,091 - util.py[DEBUG]: Copying /usr/sbin/dhclient to /var/tmp/cloud-init/cloud-init-dhcp-lf9xq0tz/dhclient
2021-08-13 17:06:52,094 - subp.py[DEBUG]: Running command ['ip', 'link', 'set', 'dev', 'eth0', 'up'] with allowed return codes [0] (shell=False, capture=True)
2021-08-13 17:06:52,115 - subp.py[DEBUG]: Running command ['/var/tmp/cloud-init/cloud-init-dhcp-lf9xq0tz/dhclient', '-1', '-v', '-lf', '/var/tmp/cloud-init/cloud-init-dhcp-lf9xq0tz/dhcp.leases', '-pf', '/var/tmp/cloud-init/cloud-init-dhcp-lf9xq0tz/dhclient.pid', 'eth0', '-sf', '/bin/true'] with allowed return codes [0] (shell=False, capture=True)
2021-08-13 17:06:52,170 - util.py[DEBUG]: All files appeared after 0 seconds: ['/var/tmp/cloud-init/cloud-init-dhcp-lf9xq0tz/dhclient.pid', '/var/tmp/cloud-init/cloud-init-dhcp-lf9xq0tz/dhcp.leases']
2021-08-13 17:06:52,170 - util.py[DEBUG]: Reading from /var/tmp/cloud-init/cloud-init-dhcp-lf9xq0tz/dhclient.pid (quiet=False)
2021-08-13 17:06:52,170 - util.py[DEBUG]: Read 4 bytes from /var/tmp/cloud-init/cloud-init-dhcp-lf9xq0tz/dhclient.pid
2021-08-13 17:06:52,170 - util.py[DEBUG]: Reading from /proc/341/stat (quiet=True)
2021-08-13 17:06:52,170 - util.py[DEBUG]: Read 305 bytes from /proc/341/stat
2021-08-13 17:06:52,170 - dhcp.py[DEBUG]: killing dhclient with pid=341
2021-08-13 17:06:52,171 - util.py[DEBUG]: Reading from /var/tmp/cloud-init/cloud-init-dhcp-lf9xq0tz/dhcp.leases (quiet=False)
2021-08-13 17:06:52,171 - util.py[DEBUG]: Read 514 bytes from /var/tmp/cloud-init/cloud-init-dhcp-lf9xq0tz/dhcp.leases
2021-08-13 17:06:52,172 - dhcp.py[DEBUG]: Received dhcp lease on eth0 for 172.31.42.60/255.255.240.0
2021-08-13 17:06:52,172 - __init__.py[DEBUG]: Attempting setup of ephemeral network on eth0 with 172.31.42.60/20 brd 172.31.47.255
2021-08-13 17:06:52,172 - subp.py[DEBUG]: Running command ['ip', '-family', 'inet', 'addr', 'add', '172.31.42.60/20', 'broadcast', '172.31.47.255', 'dev', 'eth0'] with allowed return codes [0] (shell=False, capture=True)
2021-08-13 17:06:52,179 - subp.py[DEBUG]: Running command ['ip', '-family', 'inet', 'link', 'set', 'dev', 'eth0', 'up'] with allowed return codes [0] (shell=False, capture=True)
2021-08-13 17:06:52,182 - subp.py[DEBUG]: Running command ['ip', 'route', 'show', '0.0.0.0/0'] with allowed return codes [0] (shell=False, capture=True)
2021-08-13 17:06:52,190 - subp.py[DEBUG]: Running command ['ip', '-4', 'route', 'add', '172.31.32.1', 'dev', 'eth0', 'src', '172.31.42.60'] with allowed return codes [0] (shell=False, capture=True)
2021-08-13 17:06:52,192 - subp.py[DEBUG]: Running command ['ip', '-4', 'route', 'add', 'default', 'via', '172.31.32.1', 'dev', 'eth0'] with allowed return codes [0] (shell=False, capture=True)
2021-08-13 17:06:52,199 - util.py[DEBUG]: Resolving URL: http://169.254.169.254 took 0.001 seconds
2021-08-13 17:06:52,200 - util.py[DEBUG]: Resolving URL: http://instance-data.:8773 took 0.000 seconds
2021-08-13 17:06:52,200 - DataSourceEc2.py[DEBUG]: Removed the following from metadata urls: ['http://instance-data.:8773']
2021-08-13 17:06:52,200 - DataSourceEc2.py[DEBUG]: Fetching Ec2 IMDSv2 API Token
2021-08-13 17:06:52,200 - url_helper.py[DEBUG]: [0/1] open 'http://169.254.169.254/latest/api/token' with {'url': 'http://169.254.169.254/latest/api/token', 'allow_redirects': True, 'method': 'PUT', 'timeout': 50.0, 'headers': {'User-Agent': 'Cloud-Init/21.1-19-gbad84ad4-0ubuntu1~20.04.2', 'X-aws-ec2-metadata-token-ttl-seconds': 'REDACTED'}} configuration
2021-08-13 17:06:52,213 - url_helper.py[DEBUG]: Read from http://169.254.169.254/latest/api/token (200, 56b) after 1 attempts
2021-08-13 17:06:52,213 - DataSourceEc2.py[DEBUG]: Using metadata source: 'http://169.254.169.254'
2021-08-13 17:06:52,213 - url_helper.py[DEBUG]: [0/1] open 'http://169.254.169.254/2018-09-24/meta-data/instance-id' with {'url': 'http://169.254.169.254/2018-09-24/meta-data/instance-id', 'allow_redirects': True, 'method': 'GET', 'headers': {'User-Agent': 'Cloud-Init/21.1-19-gbad84ad4-0ubuntu1~20.04.2', 'X-aws-ec2-metadata-token': 'REDACTED'}} configuration
2021-08-13 17:06:52,216 - url_helper.py[DEBUG]: Read from http://169.254.169.254/2018-09-24/meta-data/instance-id (200, 19b) after 1 attempts
2021-08-13 17:06:52,216 - DataSourceEc2.py[DEBUG]: Found preferred metadata version 2018-09-24
2021-08-13 17:06:52,216 - url_helper.py[DEBUG]: [0/6] open 'http://169.254.169.254/2018-09-24/user-data' with {'url': 'http://169.254.169.254/2018-09-24/user-data', 'allow_redirects': True, 'method': 'GET', 'timeout': 5.0, 'headers': {'X-aws-ec2-metadata-token': 'REDACTED'}} configuration
2021-08-13 17:06:52,219 - url_helper.py[DEBUG]: [0/6] open 'http://169.254.169.254/2018-09-24/meta-data/' with {'url': 'http://169.254.169.254/2018-09-24/meta-data/', 'allow_redirects': True, 'method': 'GET', 'timeout': 5.0, 'headers': {'X-aws-ec2-metadata-token': 'REDACTED'}} configuration
2021-08-13 17:06:52,223 - url_helper.py[DEBUG]: Read from http://169.254.169.254/2018-09-24/meta-data/ (200, 293b) after 1 attempts
2021-08-13 17:06:52,223 - url_helper.py[DEBUG]: [0/6] open 'http://169.254.169.254/2018-09-24/meta-data/block-device-mapping/' with {'url': 'http://169.254.169.254/2018-09-24/meta-data/block-device-mapping/', 'allow_redirects': True, 'method': 'GET', 'timeout': 5.0, 'headers': {'X-aws-ec2-metadata-token': 'REDACTED'}} configuration
2021-08-13 17:06:52,225 - url_helper.py[DEBUG]: Read from http://169.254.169.254/2018-09-24/meta-data/block-device-mapping/ (200, 8b) after 1 attempts
2021-08-13 17:06:52,226 - url_helper.py[DEBUG]: [0/6] open 'http://169.254.169.254/2018-09-24/meta-data/block-device-mapping/ami' with {'url': 'http://169.254.169.254/2018-09-24/meta-data/block-device-mapping/ami', 'allow_redirects': True, 'method': 'GET', 'timeout': 5.0, 'headers': {'X-aws-ec2-metadata-token': 'REDACTED'}} configuration
2021-08-13 17:06:52,231 - url_helper.py[DEBUG]: Read from http://169.254.169.254/2018-09-24/meta-data/block-device-mapping/ami (200, 9b) after 1 attempts
2021-08-13 17:06:52,231 - url_helper.py[DEBUG]: [0/6] open 'http://169.254.169.254/2018-09-24/meta-data/block-device-mapping/root' with {'url': 'http://169.254.169.254/2018-09-24/meta-data/block-device-mapping/root', 'allow_redirects': True, 'method': 'GET', 'timeout': 5.0, 'headers': {'X-aws-ec2-metadata-token': 'REDACTED'}} configuration
2021-08-13 17:06:52,233 - url_helper.py[DEBUG]: Read from http://169.254.169.254/2018-09-24/meta-data/block-device-mapping/root (200, 9b) after 1 attempts
2021-08-13 17:06:52,234 - url_helper.py[DEBUG]: [0/6] open 'http://169.254.169.254/2018-09-24/meta-data/events/' with {'url': 'http://169.254.169.254/2018-09-24/meta-data/events/', 'allow_redirects': True, 'method': 'GET', 'timeout': 5.0, 'headers': {'X-aws-ec2-metadata-token': 'REDACTED'}} configuration
2021-08-13 17:06:52,236 - url_helper.py[DEBUG]: Read from http://169.254.169.254/2018-09-24/meta-data/events/ (200, 12b) after 1 attempts
2021-08-13 17:06:52,236 - url_helper.py[DEBUG]: [0/6] open 'http://169.254.169.254/2018-09-24/meta-data/events/maintenance/' with {'url': 'http://169.254.169.254/2018-09-24/meta-data/events/maintenance/', 'allow_redirects': True, 'method': 'GET', 'timeout': 5.0, 'headers': {'X-aws-ec2-metadata-token': 'REDACTED'}} configuration
2021-08-13 17:06:52,239 - url_helper.py[DEBUG]: Read from http://169.254.169.254/2018-09-24/meta-data/events/maintenance/ (200, 17b) after 1 attempts
2021-08-13 17:06:52,239 - url_helper.py[DEBUG]: [0/6] open 'http://169.254.169.254/2018-09-24/meta-data/events/maintenance/history' with {'url': 'http://169.254.169.254/2018-09-24/meta-data/events/maintenance/history', 'allow_redirects': True, 'method': 'GET', 'timeout': 5.0, 'headers': {'X-aws-ec2-metadata-token': 'REDACTED'}} configuration
2021-08-13 17:06:52,243 - url_helper.py[DEBUG]: Read from http://169.254.169.254/2018-09-24/meta-data/events/maintenance/history (200, 2b) after 1 attempts
2021-08-13 17:06:52,243 - url_helper.py[DEBUG]: [0/6] open 'http://169.254.169.254/2018-09-24/meta-data/events/maintenance/scheduled' with {'url': 'http://169.254.169.254/2018-09-24/meta-data/events/maintenance/scheduled', 'allow_redirects': True, 'method': 'GET', 'timeout': 5.0, 'headers': {'X-aws-ec2-metadata-token': 'REDACTED'}} configuration
2021-08-13 17:06:52,247 - url_helper.py[DEBUG]: Read from http://169.254.169.254/2018-09-24/meta-data/events/maintenance/scheduled (200, 2b) after 1 attempts
2021-08-13 17:06:52,247 - url_helper.py[DEBUG]: [0/6] open 'http://169.254.169.254/2018-09-24/meta-data/identity-credentials/' with {'url': 'http://169.254.169.254/2018-09-24/meta-data/identity-credentials/', 'allow_redirects': True, 'method': 'GET', 'timeout': 5.0, 'headers': {'X-aws-ec2-metadata-token': 'REDACTED'}} configuration
2021-08-13 17:06:52,250 - url_helper.py[DEBUG]: Read from http://169.254.169.254/2018-09-24/meta-data/identity-credentials/ (200, 4b) after 1 attempts
2021-08-13 17:06:52,250 - url_helper.py[DEBUG]: [0/6] open 'http://169.254.169.254/2018-09-24/meta-data/identity-credentials/ec2/' with {'url': 'http://169.254.169.254/2018-09-24/meta-data/identity-credentials/ec2/', 'allow_redirects': True, 'method': 'GET', 'timeout': 5.0, 'headers': {'X-aws-ec2-metadata-token': 'REDACTED'}} configuration
2021-08-13 17:06:52,252 - url_helper.py[DEBUG]: Read from http://169.254.169.254/2018-09-24/meta-data/identity-credentials/ec2/ (200, 26b) after 1 attempts
2021-08-13 17:06:52,253 - url_helper.py[DEBUG]: [0/6] open 'http://169.254.169.254/2018-09-24/meta-data/identity-credentials/ec2/info' with {'url': 'http://169.254.169.254/2018-09-24/meta-data/identity-credentials/ec2/info', 'allow_redirects': True, 'method': 'GET', 'timeout': 5.0, 'headers': {'X-aws-ec2-metadata-token': 'REDACTED'}} configuration
2021-08-13 17:06:52,255 - url_helper.py[DEBUG]: Read from http://169.254.169.254/2018-09-24/meta-data/identity-credentials/ec2/info (200, 98b) after 1 attempts
2021-08-13 17:06:52,255 - url_helper.py[DEBUG]: [0/6] open 'http://169.254.169.254/2018-09-24/meta-data/metrics/' with {'url': 'http://169.254.169.254/2018-09-24/meta-data/metrics/', 'allow_redirects': True, 'method': 'GET', 'timeout': 5.0, 'headers': {'X-aws-ec2-metadata-token': 'REDACTED'}} configuration
2021-08-13 17:06:52,259 - url_helper.py[DEBUG]: Read from http://169.254.169.254/2018-09-24/meta-data/metrics/ (200, 7b) after 1 attempts
2021-08-13 17:06:52,259 - url_helper.py[DEBUG]: [0/6] open 'http://169.254.169.254/2018-09-24/meta-data/metrics/vhostmd' with {'url': 'http://169.254.169.254/2018-09-24/meta-data/metrics/vhostmd', 'allow_redirects': True, 'method': 'GET', 'timeout': 5.0, 'headers': {'X-aws-ec2-metadata-token': 'REDACTED'}} configuration
2021-08-13 17:06:52,263 - url_helper.py[DEBUG]: Read from http://169.254.169.254/2018-09-24/meta-data/metrics/vhostmd (200, 38b) after 1 attempts
2021-08-13 17:06:52,263 - url_helper.py[DEBUG]: [0/6] open 'http://169.254.169.254/2018-09-24/meta-data/network/' with {'url': 'http://169.254.169.254/2018-09-24/meta-data/network/', 'allow_redirects': True, 'method': 'GET', 'timeout': 5.0, 'headers': {'X-aws-ec2-metadata-token': 'REDACTED'}} configuration
2021-08-13 17:06:52,265 - url_helper.py[DEBUG]: Read from http://169.254.169.254/2018-09-24/meta-data/network/ (200, 11b) after 1 attempts
2021-08-13 17:06:52,265 - url_helper.py[DEBUG]: [0/6] open 'http://169.254.169.254/2018-09-24/meta-data/network/interfaces/' with {'url': 'http://169.254.169.254/2018-09-24/meta-data/network/interfaces/', 'allow_redirects': True, 'method': 'GET', 'timeout': 5.0, 'headers': {'X-aws-ec2-metadata-token': 'REDACTED'}} configuration
2021-08-13 17:06:52,271 - url_helper.py[DEBUG]: Read from http://169.254.169.254/2018-09-24/meta-data/network/interfaces/ (200, 5b) after 1 attempts
2021-08-13 17:06:52,271 - url_helper.py[DEBUG]: [0/6] open 'http://169.254.169.254/2018-09-24/meta-data/network/interfaces/macs/' with {'url': 'http://169.254.169.254/2018-09-24/meta-data/network/interfaces/macs/', 'allow_redirects': True, 'method': 'GET', 'timeout': 5.0, 'headers': {'X-aws-ec2-metadata-token': 'REDACTED'}} configuration
2021-08-13 17:06:52,273 - url_helper.py[DEBUG]: Read from http://169.254.169.254/2018-09-24/meta-data/network/interfaces/macs/ (200, 18b) after 1 attempts
2021-08-13 17:06:52,273 - url_helper.py[DEBUG]: [0/6] open 'http://169.254.169.254/2018-09-24/meta-data/network/interfaces/macs/0e:ba:5e:ce:5f:17/' with {'url': 'http://169.254.169.254/2018-09-24/meta-data/network/interfaces/macs/0e:ba:5e:ce:5f:17/', 'allow_redirects': True, 'method': 'GET', 'timeout': 5.0, 'headers': {'X-aws-ec2-metadata-token': 'REDACTED'}} configuration
2021-08-13 17:06:52,276 - url_helper.py[DEBUG]: Read from http://169.254.169.254/2018-09-24/meta-data/network/interfaces/macs/0e:ba:5e:ce:5f:17/ (200, 230b) after 1 attempts
2021-08-13 17:06:52,276 - url_helper.py[DEBUG]: [0/6] open 'http://169.254.169.254/2018-09-24/meta-data/network/interfaces/macs/0e:ba:5e:ce:5f:17/ipv4-associations/' with {'url': 'http://169.254.169.254/2018-09-24/meta-data/network/interfaces/macs/0e:ba:5e:ce:5f:17/ipv4-associations/', 'allow_redirects': True, 'method': 'GET', 'timeout': 5.0, 'headers': {'X-aws-ec2-metadata-token': 'REDACTED'}} configuration
2021-08-13 17:06:52,279 - url_helper.py[DEBUG]: Read from http://169.254.169.254/2018-09-24/meta-data/network/interfaces/macs/0e:ba:5e:ce:5f:17/ipv4-associations/ (200, 14b) after 1 attempts
2021-08-13 17:06:52,279 - url_helper.py[DEBUG]: [0/6] open 'http://169.254.169.254/2018-09-24/meta-data/network/interfaces/macs/0e:ba:5e:ce:5f:17/ipv4-associations/34.207.102.197' with {'url': 'http://169.254.169.254/2018-09-24/meta-data/network/interfaces/macs/0e:ba:5e:ce:5f:17/ipv4-associations/34.207.102.197', 'allow_redirects': True, 'method': 'GET', 'timeout': 5.0, 'headers': {'X-aws-ec2-metadata-token': 'REDACTED'}} configuration
2021-08-13 17:06:52,283 - url_helper.py[DEBUG]: Read from http://169.254.169.254/2018-09-24/meta-data/network/interfaces/macs/0e:ba:5e:ce:5f:17/ipv4-associations/34.207.102.197 (200, 12b) after 1 attempts
2021-08-13 17:06:52,283 - url_helper.py[DEBUG]: [0/6] open 'http://169.254.169.254/2018-09-24/meta-data/network/interfaces/macs/0e:ba:5e:ce:5f:17/device-number' with {'url': 'http://169.254.169.254/2018-09-24/meta-data/network/interfaces/macs/0e:ba:5e:ce:5f:17/device-number', 'allow_redirects': True, 'method': 'GET', 'timeout': 5.0, 'headers': {'X-aws-ec2-metadata-token': 'REDACTED'}} configuration
2021-08-13 17:06:52,287 - url_helper.py[DEBUG]: Read from http://169.254.169.254/2018-09-24/meta-data/network/interfaces/macs/0e:ba:5e:ce:5f:17/device-number (200, 1b) after 1 attempts
2021-08-13 17:06:52,287 - url_helper.py[DEBUG]: [0/6] open 'http://169.254.169.254/2018-09-24/meta-data/network/interfaces/macs/0e:ba:5e:ce:5f:17/interface-id' with {'url': 'http://169.254.169.254/2018-09-24/meta-data/network/interfaces/macs/0e:ba:5e:ce:5f:17/interface-id', 'allow_redirects': True, 'method': 'GET', 'timeout': 5.0, 'headers': {'X-aws-ec2-metadata-token': 'REDACTED'}} configuration
2021-08-13 17:06:52,289 - url_helper.py[DEBUG]: Read from http://169.254.169.254/2018-09-24/meta-data/network/interfaces/macs/0e:ba:5e:ce:5f:17/interface-id (200, 21b) after 1 attempts
2021-08-13 17:06:52,290 - url_helper.py[DEBUG]: [0/6] open 'http://169.254.169.254/2018-09-24/meta-data/network/interfaces/macs/0e:ba:5e:ce:5f:17/local-hostname' with {'url': 'http://169.254.169.254/2018-09-24/meta-data/network/interfaces/macs/0e:ba:5e:ce:5f:17/local-hostname', 'allow_redirects': True, 'method': 'GET', 'timeout': 5.0, 'headers': {'X-aws-ec2-metadata-token': 'REDACTED'}} configuration
2021-08-13 17:06:52,295 - url_helper.py[DEBUG]: Read from http://169.254.169.254/2018-09-24/meta-data/network/interfaces/macs/0e:ba:5e:ce:5f:17/local-hostname (200, 28b) after 1 attempts
2021-08-13 17:06:52,295 - url_helper.py[DEBUG]: [0/6] open 'http://169.254.169.254/2018-09-24/meta-data/network/interfaces/macs/0e:ba:5e:ce:5f:17/local-ipv4s' with {'url': 'http://169.254.169.254/2018-09-24/meta-data/network/interfaces/macs/0e:ba:5e:ce:5f:17/local-ipv4s', 'allow_redirects': True, 'method': 'GET', 'timeout': 5.0, 'headers': {'X-aws-ec2-metadata-token': 'REDACTED'}} configuration
2021-08-13 17:06:52,298 - url_helper.py[DEBUG]: Read from http://169.254.169.254/2018-09-24/meta-data/network/interfaces/macs/0e:ba:5e:ce:5f:17/local-ipv4s (200, 12b) after 1 attempts
2021-08-13 17:06:52,298 - url_helper.py[DEBUG]: [0/6] open 'http://169.254.169.254/2018-09-24/meta-data/network/interfaces/macs/0e:ba:5e:ce:5f:17/mac' with {'url': 'http://169.254.169.254/2018-09-24/meta-data/network/interfaces/macs/0e:ba:5e:ce:5f:17/mac', 'allow_redirects': True, 'method': 'GET', 'timeout': 5.0, 'headers': {'X-aws-ec2-metadata-token': 'REDACTED'}} configuration
2021-08-13 17:06:52,303 - url_helper.py[DEBUG]: Read from http://169.254.169.254/2018-09-24/meta-data/network/interfaces/macs/0e:ba:5e:ce:5f:17/mac (200, 17b) after 1 attempts
2021-08-13 17:06:52,303 - url_helper.py[DEBUG]: [0/6] open 'http://169.254.169.254/2018-09-24/meta-data/network/interfaces/macs/0e:ba:5e:ce:5f:17/owner-id' with {'url': 'http://169.254.169.254/2018-09-24/meta-data/network/interfaces/macs/0e:ba:5e:ce:5f:17/owner-id', 'allow_redirects': True, 'method': 'GET', 'timeout': 5.0, 'headers': {'X-aws-ec2-metadata-token': 'REDACTED'}} configuration
2021-08-13 17:06:52,305 - url_helper.py[DEBUG]: Read from http://169.254.169.254/2018-09-24/meta-data/network/interfaces/macs/0e:ba:5e:ce:5f:17/owner-id (200, 12b) after 1 attempts
2021-08-13 17:06:52,305 - url_helper.py[DEBUG]: [0/6] open 'http://169.254.169.254/2018-09-24/meta-data/network/interfaces/macs/0e:ba:5e:ce:5f:17/public-hostname' with {'url': 'http://169.254.169.254/2018-09-24/meta-data/network/interfaces/macs/0e:ba:5e:ce:5f:17/public-hostname', 'allow_redirects': True, 'method': 'GET', 'timeout': 5.0, 'headers': {'X-aws-ec2-metadata-token': 'REDACTED'}} configuration
2021-08-13 17:06:52,311 - url_helper.py[DEBUG]: Read from http://169.254.169.254/2018-09-24/meta-data/network/interfaces/macs/0e:ba:5e:ce:5f:17/public-hostname (200, 42b) after 1 attempts
2021-08-13 17:06:52,311 - url_helper.py[DEBUG]: [0/6] open 'http://169.254.169.254/2018-09-24/meta-data/network/interfaces/macs/0e:ba:5e:ce:5f:17/public-ipv4s' with {'url': 'http://169.254.169.254/2018-09-24/meta-data/network/interfaces/macs/0e:ba:5e:ce:5f:17/public-ipv4s', 'allow_redirects': True, 'method': 'GET', 'timeout': 5.0, 'headers': {'X-aws-ec2-metadata-token': 'REDACTED'}} configuration
2021-08-13 17:06:52,314 - url_helper.py[DEBUG]: Read from http://169.254.169.254/2018-09-24/meta-data/network/interfaces/macs/0e:ba:5e:ce:5f:17/public-ipv4s (200, 14b) after 1 attempts
2021-08-13 17:06:52,314 - url_helper.py[DEBUG]: [0/6] open 'http://169.254.169.254/2018-09-24/meta-data/network/interfaces/macs/0e:ba:5e:ce:5f:17/security-group-ids' with {'url': 'http://169.254.169.254/2018-09-24/meta-data/network/interfaces/macs/0e:ba:5e:ce:5f:17/security-group-ids', 'allow_redirects': True, 'method': 'GET', 'timeout': 5.0, 'headers': {'X-aws-ec2-metadata-token': 'REDACTED'}} configuration
2021-08-13 17:06:52,317 - url_helper.py[DEBUG]: Read from http://169.254.169.254/2018-09-24/meta-data/network/interfaces/macs/0e:ba:5e:ce:5f:17/security-group-ids (200, 20b) after 1 attempts
2021-08-13 17:06:52,317 - url_helper.py[DEBUG]: [0/6] open 'http://169.254.169.254/2018-09-24/meta-data/network/interfaces/macs/0e:ba:5e:ce:5f:17/security-groups' with {'url': 'http://169.254.169.254/2018-09-24/meta-data/network/interfaces/macs/0e:ba:5e:ce:5f:17/security-groups', 'allow_redirects': True, 'method': 'GET', 'timeout': 5.0, 'headers': {'X-aws-ec2-metadata-token': 'REDACTED'}} configuration
2021-08-13 17:06:52,323 - url_helper.py[DEBUG]: Read from http://169.254.169.254/2018-09-24/meta-data/network/interfaces/macs/0e:ba:5e:ce:5f:17/security-groups (200, 16b) after 1 attempts
2021-08-13 17:06:52,323 - url_helper.py[DEBUG]: [0/6] open 'http://169.254.169.254/2018-09-24/meta-data/network/interfaces/macs/0e:ba:5e:ce:5f:17/subnet-id' with {'url': 'http://169.254.169.254/2018-09-24/meta-data/network/interfaces/macs/0e:ba:5e:ce:5f:17/subnet-id', 'allow_redirects': True, 'method': 'GET', 'timeout': 5.0, 'headers': {'X-aws-ec2-metadata-token': 'REDACTED'}} configuration
2021-08-13 17:06:52,326 - url_helper.py[DEBUG]: Read from http://169.254.169.254/2018-09-24/meta-data/network/interfaces/macs/0e:ba:5e:ce:5f:17/subnet-id (200, 15b) after 1 attempts
2021-08-13 17:06:52,326 - url_helper.py[DEBUG]: [0/6] open 'http://169.254.169.254/2018-09-24/meta-data/network/interfaces/macs/0e:ba:5e:ce:5f:17/subnet-ipv4-cidr-block' with {'url': 'http://169.254.169.254/2018-09-24/meta-data/network/interfaces/macs/0e:ba:5e:ce:5f:17/subnet-ipv4-cidr-block', 'allow_redirects': True, 'method': 'GET', 'timeout': 5.0, 'headers': {'X-aws-ec2-metadata-token': 'REDACTED'}} configuration
2021-08-13 17:06:52,331 - url_helper.py[DEBUG]: Read from http://169.254.169.254/2018-09-24/meta-data/network/interfaces/macs/0e:ba:5e:ce:5f:17/subnet-ipv4-cidr-block (200, 14b) after 1 attempts
2021-08-13 17:06:52,331 - url_helper.py[DEBUG]: [0/6] open 'http://169.254.169.254/2018-09-24/meta-data/network/interfaces/macs/0e:ba:5e:ce:5f:17/vpc-id' with {'url': 'http://169.254.169.254/2018-09-24/meta-data/network/interfaces/macs/0e:ba:5e:ce:5f:17/vpc-id', 'allow_redirects': True, 'method': 'GET', 'timeout': 5.0, 'headers': {'X-aws-ec2-metadata-token': 'REDACTED'}} configuration
2021-08-13 17:06:52,334 - url_helper.py[DEBUG]: Read from http://169.254.169.254/2018-09-24/meta-data/network/interfaces/macs/0e:ba:5e:ce:5f:17/vpc-id (200, 12b) after 1 attempts
2021-08-13 17:06:52,334 - url_helper.py[DEBUG]: [0/6] open 'http://169.254.169.254/2018-09-24/meta-data/network/interfaces/macs/0e:ba:5e:ce:5f:17/vpc-ipv4-cidr-block' with {'url': 'http://169.254.169.254/2018-09-24/meta-data/network/interfaces/macs/0e:ba:5e:ce:5f:17/vpc-ipv4-cidr-block', 'allow_redirects': True, 'method': 'GET', 'timeout': 5.0, 'headers': {'X-aws-ec2-metadata-token': 'REDACTED'}} configuration
2021-08-13 17:06:52,338 - url_helper.py[DEBUG]: Read from http://169.254.169.254/2018-09-24/meta-data/network/interfaces/macs/0e:ba:5e:ce:5f:17/vpc-ipv4-cidr-block (200, 13b) after 1 attempts
2021-08-13 17:06:52,338 - url_helper.py[DEBUG]: [0/6] open 'http://169.254.169.254/2018-09-24/meta-data/network/interfaces/macs/0e:ba:5e:ce:5f:17/vpc-ipv4-cidr-blocks' with {'url': 'http://169.254.169.254/2018-09-24/meta-data/network/interfaces/macs/0e:ba:5e:ce:5f:17/vpc-ipv4-cidr-blocks', 'allow_redirects': True, 'method': 'GET', 'timeout': 5.0, 'headers': {'X-aws-ec2-metadata-token': 'REDACTED'}} configuration
2021-08-13 17:06:52,340 - url_helper.py[DEBUG]: Read from http://169.254.169.254/2018-09-24/meta-data/network/interfaces/macs/0e:ba:5e:ce:5f:17/vpc-ipv4-cidr-blocks (200, 13b) after 1 attempts
2021-08-13 17:06:52,341 - url_helper.py[DEBUG]: [0/6] open 'http://169.254.169.254/2018-09-24/meta-data/placement/' with {'url': 'http://169.254.169.254/2018-09-24/meta-data/placement/', 'allow_redirects': True, 'method': 'GET', 'timeout': 5.0, 'headers': {'X-aws-ec2-metadata-token': 'REDACTED'}} configuration
2021-08-13 17:06:52,343 - url_helper.py[DEBUG]: Read from http://169.254.169.254/2018-09-24/meta-data/placement/ (200, 17b) after 1 attempts
2021-08-13 17:06:52,344 - url_helper.py[DEBUG]: [0/6] open 'http://169.254.169.254/2018-09-24/meta-data/placement/availability-zone' with {'url': 'http://169.254.169.254/2018-09-24/meta-data/placement/availability-zone', 'allow_redirects': True, 'method': 'GET', 'timeout': 5.0, 'headers': {'X-aws-ec2-metadata-token': 'REDACTED'}} configuration
2021-08-13 17:06:52,346 - url_helper.py[DEBUG]: Read from http://169.254.169.254/2018-09-24/meta-data/placement/availability-zone (200, 10b) after 1 attempts
2021-08-13 17:06:52,346 - url_helper.py[DEBUG]: [0/6] open 'http://169.254.169.254/2018-09-24/meta-data/public-keys/' with {'url': 'http://169.254.169.254/2018-09-24/meta-data/public-keys/', 'allow_redirects': True, 'method': 'GET', 'timeout': 5.0, 'headers': {'X-aws-ec2-metadata-token': 'REDACTED'}} configuration
2021-08-13 17:06:52,350 - url_helper.py[DEBUG]: Read from http://169.254.169.254/2018-09-24/meta-data/public-keys/ (200, 8b) after 1 attempts
2021-08-13 17:06:52,350 - url_helper.py[DEBUG]: [0/6] open 'http://169.254.169.254/2018-09-24/meta-data/public-keys/0/openssh-key' with {'url': 'http://169.254.169.254/2018-09-24/meta-data/public-keys/0/openssh-key', 'allow_redirects': True, 'method': 'GET', 'timeout': 5.0, 'headers': {'X-aws-ec2-metadata-token': 'REDACTED'}} configuration
2021-08-13 17:06:52,353 - url_helper.py[DEBUG]: Read from http://169.254.169.254/2018-09-24/meta-data/public-keys/0/openssh-key (200, 388b) after 1 attempts
2021-08-13 17:06:52,353 - url_helper.py[DEBUG]: [0/6] open 'http://169.254.169.254/2018-09-24/meta-data/services/' with {'url': 'http://169.254.169.254/2018-09-24/meta-data/services/', 'allow_redirects': True, 'method': 'GET', 'timeout': 5.0, 'headers': {'X-aws-ec2-metadata-token': 'REDACTED'}} configuration
2021-08-13 17:06:52,355 - url_helper.py[DEBUG]: Read from http://169.254.169.254/2018-09-24/meta-data/services/ (200, 16b) after 1 attempts
2021-08-13 17:06:52,356 - url_helper.py[DEBUG]: [0/6] open 'http://169.254.169.254/2018-09-24/meta-data/services/domain' with {'url': 'http://169.254.169.254/2018-09-24/meta-data/services/domain', 'allow_redirects': True, 'method': 'GET', 'timeout': 5.0, 'headers': {'X-aws-ec2-metadata-token': 'REDACTED'}} configuration
2021-08-13 17:06:52,358 - url_helper.py[DEBUG]: Read from http://169.254.169.254/2018-09-24/meta-data/services/domain (200, 13b) after 1 attempts
2021-08-13 17:06:52,358 - url_helper.py[DEBUG]: [0/6] open 'http://169.254.169.254/2018-09-24/meta-data/services/partition' with {'url': 'http://169.254.169.254/2018-09-24/meta-data/services/partition', 'allow_redirects': True, 'method': 'GET', 'timeout': 5.0, 'headers': {'X-aws-ec2-metadata-token': 'REDACTED'}} configuration
2021-08-13 17:06:52,360 - url_helper.py[DEBUG]: Read from http://169.254.169.254/2018-09-24/meta-data/services/partition (200, 3b) after 1 attempts
2021-08-13 17:06:52,361 - url_helper.py[DEBUG]: [0/6] open 'http://169.254.169.254/2018-09-24/meta-data/ami-id' with {'url': 'http://169.254.169.254/2018-09-24/meta-data/ami-id', 'allow_redirects': True, 'method': 'GET', 'timeout': 5.0, 'headers': {'X-aws-ec2-metadata-token': 'REDACTED'}} configuration
2021-08-13 17:06:52,370 - url_helper.py[DEBUG]: Read from http://169.254.169.254/2018-09-24/meta-data/ami-id (200, 21b) after 1 attempts
2021-08-13 17:06:52,370 - url_helper.py[DEBUG]: [0/6] open 'http://169.254.169.254/2018-09-24/meta-data/ami-launch-index' with {'url': 'http://169.254.169.254/2018-09-24/meta-data/ami-launch-index', 'allow_redirects': True, 'method': 'GET', 'timeout': 5.0, 'headers': {'X-aws-ec2-metadata-token': 'REDACTED'}} configuration
2021-08-13 17:06:52,373 - url_helper.py[DEBUG]: Read from http://169.254.169.254/2018-09-24/meta-data/ami-launch-index (200, 1b) after 1 attempts
2021-08-13 17:06:52,373 - url_helper.py[DEBUG]: [0/6] open 'http://169.254.169.254/2018-09-24/meta-data/ami-manifest-path' with {'url': 'http://169.254.169.254/2018-09-24/meta-data/ami-manifest-path', 'allow_redirects': True, 'method': 'GET', 'timeout': 5.0, 'headers': {'X-aws-ec2-metadata-token': 'REDACTED'}} configuration
2021-08-13 17:06:52,375 - url_helper.py[DEBUG]: Read from http://169.254.169.254/2018-09-24/meta-data/ami-manifest-path (200, 9b) after 1 attempts
2021-08-13 17:06:52,375 - url_helper.py[DEBUG]: [0/6] open 'http://169.254.169.254/2018-09-24/meta-data/hostname' with {'url': 'http://169.254.169.254/2018-09-24/meta-data/hostname', 'allow_redirects': True, 'method': 'GET', 'timeout': 5.0, 'headers': {'X-aws-ec2-metadata-token': 'REDACTED'}} configuration
2021-08-13 17:06:52,378 - url_helper.py[DEBUG]: Read from http://169.254.169.254/2018-09-24/meta-data/hostname (200, 28b) after 1 attempts
2021-08-13 17:06:52,378 - url_helper.py[DEBUG]: [0/6] open 'http://169.254.169.254/2018-09-24/meta-data/instance-action' with {'url': 'http://169.254.169.254/2018-09-24/meta-data/instance-action', 'allow_redirects': True, 'method': 'GET', 'timeout': 5.0, 'headers': {'X-aws-ec2-metadata-token': 'REDACTED'}} configuration
2021-08-13 17:06:52,383 - url_helper.py[DEBUG]: Read from http://169.254.169.254/2018-09-24/meta-data/instance-action (200, 4b) after 1 attempts
2021-08-13 17:06:52,383 - url_helper.py[DEBUG]: [0/6] open 'http://169.254.169.254/2018-09-24/meta-data/instance-id' with {'url': 'http://169.254.169.254/2018-09-24/meta-data/instance-id', 'allow_redirects': True, 'method': 'GET', 'timeout': 5.0, 'headers': {'X-aws-ec2-metadata-token': 'REDACTED'}} configuration
2021-08-13 17:06:52,386 - url_helper.py[DEBUG]: Read from http://169.254.169.254/2018-09-24/meta-data/instance-id (200, 19b) after 1 attempts
2021-08-13 17:06:52,386 - url_helper.py[DEBUG]: [0/6] open 'http://169.254.169.254/2018-09-24/meta-data/instance-type' with {'url': 'http://169.254.169.254/2018-09-24/meta-data/instance-type', 'allow_redirects': True, 'method': 'GET', 'timeout': 5.0, 'headers': {'X-aws-ec2-metadata-token': 'REDACTED'}} configuration
2021-08-13 17:06:52,391 - url_helper.py[DEBUG]: Read from http://169.254.169.254/2018-09-24/meta-data/instance-type (200, 8b) after 1 attempts
2021-08-13 17:06:52,391 - url_helper.py[DEBUG]: [0/6] open 'http://169.254.169.254/2018-09-24/meta-data/local-hostname' with {'url': 'http://169.254.169.254/2018-09-24/meta-data/local-hostname', 'allow_redirects': True, 'method': 'GET', 'timeout': 5.0, 'headers': {'X-aws-ec2-metadata-token': 'REDACTED'}} configuration
2021-08-13 17:06:52,394 - url_helper.py[DEBUG]: Read from http://169.254.169.254/2018-09-24/meta-data/local-hostname (200, 28b) after 1 attempts
2021-08-13 17:06:52,394 - url_helper.py[DEBUG]: [0/6] open 'http://169.254.169.254/2018-09-24/meta-data/local-ipv4' with {'url': 'http://169.254.169.254/2018-09-24/meta-data/local-ipv4', 'allow_redirects': True, 'method': 'GET', 'timeout': 5.0, 'headers': {'X-aws-ec2-metadata-token': 'REDACTED'}} configuration
2021-08-13 17:06:52,396 - url_helper.py[DEBUG]: Read from http://169.254.169.254/2018-09-24/meta-data/local-ipv4 (200, 12b) after 1 attempts
2021-08-13 17:06:52,396 - url_helper.py[DEBUG]: [0/6] open 'http://169.254.169.254/2018-09-24/meta-data/mac' with {'url': 'http://169.254.169.254/2018-09-24/meta-data/mac', 'allow_redirects': True, 'method': 'GET', 'timeout': 5.0, 'headers': {'X-aws-ec2-metadata-token': 'REDACTED'}} configuration
2021-08-13 17:06:52,403 - url_helper.py[DEBUG]: Read from http://169.254.169.254/2018-09-24/meta-data/mac (200, 17b) after 1 attempts
2021-08-13 17:06:52,403 - url_helper.py[DEBUG]: [0/6] open 'http://169.254.169.254/2018-09-24/meta-data/profile' with {'url': 'http://169.254.169.254/2018-09-24/meta-data/profile', 'allow_redirects': True, 'method': 'GET', 'timeout': 5.0, 'headers': {'X-aws-ec2-metadata-token': 'REDACTED'}} configuration
2021-08-13 17:06:52,406 - url_helper.py[DEBUG]: Read from http://169.254.169.254/2018-09-24/meta-data/profile (200, 11b) after 1 attempts
2021-08-13 17:06:52,406 - url_helper.py[DEBUG]: [0/6] open 'http://169.254.169.254/2018-09-24/meta-data/public-hostname' with {'url': 'http://169.254.169.254/2018-09-24/meta-data/public-hostname', 'allow_redirects': True, 'method': 'GET', 'timeout': 5.0, 'headers': {'X-aws-ec2-metadata-token': 'REDACTED'}} configuration
2021-08-13 17:06:52,408 - url_helper.py[DEBUG]: Read from http://169.254.169.254/2018-09-24/meta-data/public-hostname (200, 42b) after 1 attempts
2021-08-13 17:06:52,408 - url_helper.py[DEBUG]: [0/6] open 'http://169.254.169.254/2018-09-24/meta-data/public-ipv4' with {'url': 'http://169.254.169.254/2018-09-24/meta-data/public-ipv4', 'allow_redirects': True, 'method': 'GET', 'timeout': 5.0, 'headers': {'X-aws-ec2-metadata-token': 'REDACTED'}} configuration
2021-08-13 17:06:52,415 - url_helper.py[DEBUG]: Read from http://169.254.169.254/2018-09-24/meta-data/public-ipv4 (200, 14b) after 1 attempts
2021-08-13 17:06:52,415 - url_helper.py[DEBUG]: [0/6] open 'http://169.254.169.254/2018-09-24/meta-data/reservation-id' with {'url': 'http://169.254.169.254/2018-09-24/meta-data/reservation-id', 'allow_redirects': True, 'method': 'GET', 'timeout': 5.0, 'headers': {'X-aws-ec2-metadata-token': 'REDACTED'}} configuration
2021-08-13 17:06:52,417 - url_helper.py[DEBUG]: Read from http://169.254.169.254/2018-09-24/meta-data/reservation-id (200, 19b) after 1 attempts
2021-08-13 17:06:52,418 - url_helper.py[DEBUG]: [0/6] open 'http://169.254.169.254/2018-09-24/meta-data/security-groups' with {'url': 'http://169.254.169.254/2018-09-24/meta-data/security-groups', 'allow_redirects': True, 'method': 'GET', 'timeout': 5.0, 'headers': {'X-aws-ec2-metadata-token': 'REDACTED'}} configuration
2021-08-13 17:06:52,420 - url_helper.py[DEBUG]: Read from http://169.254.169.254/2018-09-24/meta-data/security-groups (200, 16b) after 1 attempts
2021-08-13 17:06:52,421 - url_helper.py[DEBUG]: [0/6] open 'http://169.254.169.254/2018-09-24/dynamic/instance-identity' with {'url': 'http://169.254.169.254/2018-09-24/dynamic/instance-identity', 'allow_redirects': True, 'method': 'GET', 'timeout': 5.0, 'headers': {'X-aws-ec2-metadata-token': 'REDACTED'}} configuration
2021-08-13 17:06:52,427 - url_helper.py[DEBUG]: Read from http://169.254.169.254/2018-09-24/dynamic/instance-identity (200, 33b) after 1 attempts
2021-08-13 17:06:52,427 - url_helper.py[DEBUG]: [0/6] open 'http://169.254.169.254/2018-09-24/dynamic/instance-identity/pkcs7' with {'url': 'http://169.254.169.254/2018-09-24/dynamic/instance-identity/pkcs7', 'allow_redirects': True, 'method': 'GET', 'timeout': 5.0, 'headers': {'X-aws-ec2-metadata-token': 'REDACTED'}} configuration
2021-08-13 17:06:52,429 - url_helper.py[DEBUG]: Read from http://169.254.169.254/2018-09-24/dynamic/instance-identity/pkcs7 (200, 1171b) after 1 attempts
2021-08-13 17:06:52,430 - url_helper.py[DEBUG]: [0/6] open 'http://169.254.169.254/2018-09-24/dynamic/instance-identity/signature' with {'url': 'http://169.254.169.254/2018-09-24/dynamic/instance-identity/signature', 'allow_redirects': True, 'method': 'GET', 'timeout': 5.0, 'headers': {'X-aws-ec2-metadata-token': 'REDACTED'}} configuration
2021-08-13 17:06:52,432 - url_helper.py[DEBUG]: Read from http://169.254.169.254/2018-09-24/dynamic/instance-identity/signature (200, 174b) after 1 attempts
2021-08-13 17:06:52,433 - url_helper.py[DEBUG]: [0/6] open 'http://169.254.169.254/2018-09-24/dynamic/instance-identity/document' with {'url': 'http://169.254.169.254/2018-09-24/dynamic/instance-identity/document', 'allow_redirects': True, 'method': 'GET', 'timeout': 5.0, 'headers': {'X-aws-ec2-metadata-token': 'REDACTED'}} configuration
2021-08-13 17:06:52,439 - url_helper.py[DEBUG]: Read from http://169.254.169.254/2018-09-24/dynamic/instance-identity/document (200, 476b) after 1 attempts
2021-08-13 17:06:52,439 - url_helper.py[DEBUG]: [0/6] open 'http://169.254.169.254/2018-09-24/dynamic/instance-identity/rsa2048' with {'url': 'http://169.254.169.254/2018-09-24/dynamic/instance-identity/rsa2048', 'allow_redirects': True, 'method': 'GET', 'timeout': 5.0, 'headers': {'X-aws-ec2-metadata-token': 'REDACTED'}} configuration
2021-08-13 17:06:52,442 - url_helper.py[DEBUG]: Read from http://169.254.169.254/2018-09-24/dynamic/instance-identity/rsa2048 (200, 1499b) after 1 attempts
2021-08-13 17:06:52,442 - util.py[DEBUG]: Crawl of metadata service took 0.243 seconds
2021-08-13 17:06:52,442 - subp.py[DEBUG]: Running command ['ip', '-4', 'route', 'del', 'default', 'dev', 'eth0'] with allowed return codes [0] (shell=False, capture=True)
2021-08-13 17:06:52,450 - subp.py[DEBUG]: Running command ['ip', '-4', 'route', 'del', '172.31.32.1', 'dev', 'eth0', 'src', '172.31.42.60'] with allowed return codes [0] (shell=False, capture=True)
2021-08-13 17:06:52,452 - subp.py[DEBUG]: Running command ['ip', '-family', 'inet', 'link', 'set', 'dev', 'eth0', 'down'] with allowed return codes [0] (shell=False, capture=True)
2021-08-13 17:06:52,459 - subp.py[DEBUG]: Running command ['ip', '-family', 'inet', 'addr', 'del', '172.31.42.60/20', 'dev', 'eth0'] with allowed return codes [0] (shell=False, capture=True)
2021-08-13 17:06:52,468 - atomic_helper.py[DEBUG]: Atomically writing to file /run/cloud-init/instance-data-sensitive.json (via temporary file /run/cloud-init/tmpx7669i92) - w: [600] 11306 bytes/chars
2021-08-13 17:06:52,469 - atomic_helper.py[DEBUG]: Atomically writing to file /run/cloud-init/instance-data.json (via temporary file /run/cloud-init/tmpf94hckde) - w: [644] 8079 bytes/chars
2021-08-13 17:06:52,469 - handlers.py[DEBUG]: finish: init-local/search-Ec2Local: SUCCESS: found local data from DataSourceEc2Local
2021-08-13 17:06:52,469 - stages.py[INFO]: Loaded datasource DataSourceEc2Local - DataSourceEc2Local
2021-08-13 17:06:52,474 - util.py[DEBUG]: Reading from /etc/cloud/cloud.cfg (quiet=False)
2021-08-13 17:06:52,474 - util.py[DEBUG]: Read 3619 bytes from /etc/cloud/cloud.cfg
2021-08-13 17:06:52,474 - util.py[DEBUG]: Attempting to load yaml from string of length 3619 with allowed root types (<class 'dict'>,)
2021-08-13 17:06:52,498 - util.py[DEBUG]: Reading from /etc/cloud/cloud.cfg.d/90_dpkg.cfg (quiet=False)
2021-08-13 17:06:52,498 - util.py[DEBUG]: Read 294 bytes from /etc/cloud/cloud.cfg.d/90_dpkg.cfg
2021-08-13 17:06:52,498 - util.py[DEBUG]: Attempting to load yaml from string of length 294 with allowed root types (<class 'dict'>,)
2021-08-13 17:06:52,500 - util.py[DEBUG]: Reading from /etc/cloud/cloud.cfg.d/05_logging.cfg (quiet=False)
2021-08-13 17:06:52,500 - util.py[DEBUG]: Read 2070 bytes from /etc/cloud/cloud.cfg.d/05_logging.cfg
2021-08-13 17:06:52,500 - util.py[DEBUG]: Attempting to load yaml from string of length 2070 with allowed root types (<class 'dict'>,)
2021-08-13 17:06:52,507 - util.py[DEBUG]: Reading from /run/cloud-init/cloud.cfg (quiet=False)
2021-08-13 17:06:52,507 - util.py[DEBUG]: Read 31 bytes from /run/cloud-init/cloud.cfg
2021-08-13 17:06:52,507 - util.py[DEBUG]: Attempting to load yaml from string of length 31 with allowed root types (<class 'dict'>,)
2021-08-13 17:06:52,508 - util.py[DEBUG]: Attempting to load yaml from string of length 0 with allowed root types (<class 'dict'>,)
2021-08-13 17:06:52,508 - util.py[DEBUG]: loaded blob returned None, returning default.
2021-08-13 17:06:52,508 - util.py[DEBUG]: Attempting to remove /var/lib/cloud/instance
2021-08-13 17:06:52,508 - util.py[DEBUG]: Creating symbolic link from '/var/lib/cloud/instance' => '/var/lib/cloud/instances/i-0d483f9ce23b7fccc'
2021-08-13 17:06:52,509 - util.py[DEBUG]: Reading from /var/lib/cloud/instances/i-0d483f9ce23b7fccc/datasource (quiet=False)
2021-08-13 17:06:52,513 - util.py[DEBUG]: Writing to /var/lib/cloud/instances/i-0d483f9ce23b7fccc/datasource - wb: [644] 39 bytes
2021-08-13 17:06:52,514 - util.py[DEBUG]: Writing to /var/lib/cloud/data/previous-datasource - wb: [644] 39 bytes
2021-08-13 17:06:52,514 - util.py[DEBUG]: Reading from /var/lib/cloud/data/instance-id (quiet=False)
2021-08-13 17:06:52,514 - stages.py[DEBUG]: previous iid found to be NO_PREVIOUS_INSTANCE_ID
2021-08-13 17:06:52,514 - util.py[DEBUG]: Writing to /var/lib/cloud/data/instance-id - wb: [644] 20 bytes
2021-08-13 17:06:52,515 - util.py[DEBUG]: Writing to /run/cloud-init/.instance-id - wb: [644] 20 bytes
2021-08-13 17:06:52,515 - util.py[DEBUG]: Writing to /var/lib/cloud/data/previous-instance-id - wb: [644] 24 bytes
2021-08-13 17:06:52,516 - util.py[DEBUG]: Writing to /var/lib/cloud/instance/obj.pkl - wb: [400] 11083 bytes
2021-08-13 17:06:52,516 - main.py[DEBUG]: [local] init will now be targeting instance id: i-0d483f9ce23b7fccc. new=True
2021-08-13 17:06:52,516 - util.py[DEBUG]: Reading from /etc/cloud/cloud.cfg (quiet=False)
2021-08-13 17:06:52,516 - util.py[DEBUG]: Read 3619 bytes from /etc/cloud/cloud.cfg
2021-08-13 17:06:52,516 - util.py[DEBUG]: Attempting to load yaml from string of length 3619 with allowed root types (<class 'dict'>,)
2021-08-13 17:06:52,538 - util.py[DEBUG]: Reading from /etc/cloud/cloud.cfg.d/90_dpkg.cfg (quiet=False)
2021-08-13 17:06:52,538 - util.py[DEBUG]: Read 294 bytes from /etc/cloud/cloud.cfg.d/90_dpkg.cfg
2021-08-13 17:06:52,538 - util.py[DEBUG]: Attempting to load yaml from string of length 294 with allowed root types (<class 'dict'>,)
2021-08-13 17:06:52,540 - util.py[DEBUG]: Reading from /etc/cloud/cloud.cfg.d/05_logging.cfg (quiet=False)
2021-08-13 17:06:52,540 - util.py[DEBUG]: Read 2070 bytes from /etc/cloud/cloud.cfg.d/05_logging.cfg
2021-08-13 17:06:52,540 - util.py[DEBUG]: Attempting to load yaml from string of length 2070 with allowed root types (<class 'dict'>,)
2021-08-13 17:06:52,547 - util.py[DEBUG]: Reading from /run/cloud-init/cloud.cfg (quiet=False)
2021-08-13 17:06:52,547 - util.py[DEBUG]: Read 31 bytes from /run/cloud-init/cloud.cfg
2021-08-13 17:06:52,547 - util.py[DEBUG]: Attempting to load yaml from string of length 31 with allowed root types (<class 'dict'>,)
2021-08-13 17:06:52,548 - util.py[DEBUG]: Attempting to load yaml from string of length 0 with allowed root types (<class 'dict'>,)
2021-08-13 17:06:52,548 - util.py[DEBUG]: loaded blob returned None, returning default.
2021-08-13 17:06:52,549 - stages.py[DEBUG]: Using distro class <class 'cloudinit.distros.ubuntu.Distro'>
2021-08-13 17:06:52,549 - cc_set_hostname.py[DEBUG]: Setting the hostname to ip-172-31-42-60.ec2.internal (ip-172-31-42-60)
2021-08-13 17:06:52,553 - util.py[DEBUG]: Reading from /etc/hostname (quiet=False)
2021-08-13 17:06:52,553 - util.py[DEBUG]: Read 7 bytes from /etc/hostname
2021-08-13 17:06:52,554 - util.py[DEBUG]: Writing to /etc/hostname - wb: [644] 16 bytes
2021-08-13 17:06:52,554 - __init__.py[DEBUG]: Non-persistently setting the system hostname to ip-172-31-42-60
2021-08-13 17:06:52,554 - subp.py[DEBUG]: Running command ['hostname', 'ip-172-31-42-60'] with allowed return codes [0] (shell=False, capture=True)
2021-08-13 17:06:52,560 - atomic_helper.py[DEBUG]: Atomically writing to file /var/lib/cloud/data/set-hostname (via temporary file /var/lib/cloud/data/tmp_oxz8e95) - w: [644] 76 bytes/chars
2021-08-13 17:06:52,561 - util.py[DEBUG]: Reading from /sys/class/net/eth0/address (quiet=False)
2021-08-13 17:06:52,561 - util.py[DEBUG]: Read 18 bytes from /sys/class/net/eth0/address
2021-08-13 17:06:52,561 - util.py[DEBUG]: Reading from /sys/class/net/lo/address (quiet=False)
2021-08-13 17:06:52,561 - util.py[DEBUG]: Read 18 bytes from /sys/class/net/lo/address
2021-08-13 17:06:52,566 - util.py[DEBUG]: Reading from /sys/class/net/eth0/addr_assign_type (quiet=False)
2021-08-13 17:06:52,566 - util.py[DEBUG]: Read 2 bytes from /sys/class/net/eth0/addr_assign_type
2021-08-13 17:06:52,566 - util.py[DEBUG]: Reading from /sys/class/net/eth0/uevent (quiet=False)
2021-08-13 17:06:52,566 - util.py[DEBUG]: Read 25 bytes from /sys/class/net/eth0/uevent
2021-08-13 17:06:52,566 - util.py[DEBUG]: Reading from /sys/class/net/eth0/address (quiet=False)
2021-08-13 17:06:52,566 - util.py[DEBUG]: Read 18 bytes from /sys/class/net/eth0/address
2021-08-13 17:06:52,566 - __init__.py[DEBUG]: ovs-vsctl not in PATH; not detecting Open vSwitch interfaces
2021-08-13 17:06:52,566 - util.py[DEBUG]: Reading from /sys/class/net/eth0/device/device (quiet=False)
2021-08-13 17:06:52,567 - util.py[DEBUG]: Reading from /sys/class/net/lo/addr_assign_type (quiet=False)
2021-08-13 17:06:52,567 - util.py[DEBUG]: Read 2 bytes from /sys/class/net/lo/addr_assign_type
2021-08-13 17:06:52,567 - util.py[DEBUG]: Reading from /sys/class/net/lo/uevent (quiet=False)
2021-08-13 17:06:52,567 - util.py[DEBUG]: Read 23 bytes from /sys/class/net/lo/uevent
2021-08-13 17:06:52,567 - util.py[DEBUG]: Reading from /sys/class/net/lo/address (quiet=False)
2021-08-13 17:06:52,567 - util.py[DEBUG]: Read 18 bytes from /sys/class/net/lo/address
2021-08-13 17:06:52,567 - util.py[DEBUG]: Reading from /sys/class/net/lo/device/device (quiet=False)
2021-08-13 17:06:52,567 - util.py[DEBUG]: Reading from /sys/class/net/eth0/type (quiet=False)
2021-08-13 17:06:52,567 - util.py[DEBUG]: Read 2 bytes from /sys/class/net/eth0/type
2021-08-13 17:06:52,567 - util.py[DEBUG]: Reading from /sys/class/net/lo/type (quiet=False)
2021-08-13 17:06:52,567 - util.py[DEBUG]: Read 4 bytes from /sys/class/net/lo/type
2021-08-13 17:06:52,567 - util.py[DEBUG]: Reading from /sys/class/net/eth0/device/device (quiet=False)
2021-08-13 17:06:52,567 - util.py[DEBUG]: Reading from /sys/class/net/eth0/addr_assign_type (quiet=False)
2021-08-13 17:06:52,568 - util.py[DEBUG]: Read 2 bytes from /sys/class/net/eth0/addr_assign_type
2021-08-13 17:06:52,568 - util.py[DEBUG]: Reading from /sys/class/net/eth0/uevent (quiet=False)
2021-08-13 17:06:52,568 - util.py[DEBUG]: Read 25 bytes from /sys/class/net/eth0/uevent
2021-08-13 17:06:52,568 - util.py[DEBUG]: Reading from /sys/class/net/eth0/address (quiet=False)
2021-08-13 17:06:52,568 - util.py[DEBUG]: Read 18 bytes from /sys/class/net/eth0/address
2021-08-13 17:06:52,568 - util.py[DEBUG]: Reading from /sys/class/net/eth0/device/device (quiet=False)
2021-08-13 17:06:52,568 - util.py[DEBUG]: Reading from /sys/class/net/lo/addr_assign_type (quiet=False)
2021-08-13 17:06:52,568 - util.py[DEBUG]: Read 2 bytes from /sys/class/net/lo/addr_assign_type
2021-08-13 17:06:52,568 - util.py[DEBUG]: Reading from /sys/class/net/lo/uevent (quiet=False)
2021-08-13 17:06:52,568 - util.py[DEBUG]: Read 23 bytes from /sys/class/net/lo/uevent
2021-08-13 17:06:52,568 - util.py[DEBUG]: Reading from /sys/class/net/lo/address (quiet=False)
2021-08-13 17:06:52,568 - util.py[DEBUG]: Read 18 bytes from /sys/class/net/lo/address
2021-08-13 17:06:52,568 - util.py[DEBUG]: Reading from /sys/class/net/lo/device/device (quiet=False)
2021-08-13 17:06:52,569 - util.py[DEBUG]: Reading from /sys/class/net/eth0/type (quiet=False)
2021-08-13 17:06:52,569 - util.py[DEBUG]: Read 2 bytes from /sys/class/net/eth0/type
2021-08-13 17:06:52,569 - util.py[DEBUG]: Reading from /sys/class/net/lo/type (quiet=False)
2021-08-13 17:06:52,569 - util.py[DEBUG]: Read 4 bytes from /sys/class/net/lo/type
2021-08-13 17:06:52,569 - networking.py[DEBUG]: net: all expected physical devices present
2021-08-13 17:06:52,569 - stages.py[DEBUG]: applying net config names for {'version': 2, 'ethernets': {'eth0': {'dhcp4': True, 'dhcp6': False, 'match': {'macaddress': '0e:ba:5e:ce:5f:17'}, 'set-name': 'eth0'}}}
2021-08-13 17:06:52,569 - util.py[DEBUG]: Reading from /sys/class/net/eth0/device/device (quiet=False)
2021-08-13 17:06:52,569 - util.py[DEBUG]: Reading from /sys/class/net/eth0/addr_assign_type (quiet=False)
2021-08-13 17:06:52,569 - util.py[DEBUG]: Read 2 bytes from /sys/class/net/eth0/addr_assign_type
2021-08-13 17:06:52,569 - util.py[DEBUG]: Reading from /sys/class/net/eth0/uevent (quiet=False)
2021-08-13 17:06:52,569 - util.py[DEBUG]: Read 25 bytes from /sys/class/net/eth0/uevent
2021-08-13 17:06:52,573 - util.py[DEBUG]: Reading from /sys/class/net/eth0/address (quiet=False)
2021-08-13 17:06:52,574 - util.py[DEBUG]: Read 18 bytes from /sys/class/net/eth0/address
2021-08-13 17:06:52,574 - util.py[DEBUG]: Reading from /sys/class/net/eth0/device/device (quiet=False)
2021-08-13 17:06:52,574 - util.py[DEBUG]: Reading from /sys/class/net/lo/addr_assign_type (quiet=False)
2021-08-13 17:06:52,574 - util.py[DEBUG]: Read 2 bytes from /sys/class/net/lo/addr_assign_type
2021-08-13 17:06:52,574 - util.py[DEBUG]: Reading from /sys/class/net/lo/uevent (quiet=False)
2021-08-13 17:06:52,574 - util.py[DEBUG]: Read 23 bytes from /sys/class/net/lo/uevent
2021-08-13 17:06:52,574 - util.py[DEBUG]: Reading from /sys/class/net/lo/address (quiet=False)
2021-08-13 17:06:52,574 - util.py[DEBUG]: Read 18 bytes from /sys/class/net/lo/address
2021-08-13 17:06:52,574 - util.py[DEBUG]: Reading from /sys/class/net/lo/device/device (quiet=False)
2021-08-13 17:06:52,574 - util.py[DEBUG]: Reading from /sys/class/net/eth0/operstate (quiet=False)
2021-08-13 17:06:52,574 - util.py[DEBUG]: Read 5 bytes from /sys/class/net/eth0/operstate
2021-08-13 17:06:52,574 - util.py[DEBUG]: Reading from /sys/class/net/lo/operstate (quiet=False)
2021-08-13 17:06:52,574 - util.py[DEBUG]: Read 8 bytes from /sys/class/net/lo/operstate
2021-08-13 17:06:52,575 - subp.py[DEBUG]: Running command ['ip', '-6', 'addr', 'show', 'permanent', 'scope', 'global'] with allowed return codes [0] (shell=False, capture=True)
2021-08-13 17:06:52,582 - subp.py[DEBUG]: Running command ['ip', '-4', 'addr', 'show'] with allowed return codes [0] (shell=False, capture=True)
2021-08-13 17:06:52,586 - __init__.py[DEBUG]: no work necessary for renaming of [['0e:ba:5e:ce:5f:17', 'eth0', 'vif', None]]
2021-08-13 17:06:52,586 - stages.py[INFO]: Applying network configuration from ds bringup=False: {'version': 2, 'ethernets': {'eth0': {'dhcp4': True, 'dhcp6': False, 'match': {'macaddress': '0e:ba:5e:ce:5f:17'}, 'set-name': 'eth0'}}}
2021-08-13 17:06:52,592 - __init__.py[DEBUG]: Selected renderer 'netplan' from priority list: ['netplan', 'eni', 'sysconfig']
2021-08-13 17:06:52,592 - network_state.py[DEBUG]: v2(ethernets) -> v1(physical):
{'type': 'physical', 'name': 'eth0', 'mac_address': '0e:ba:5e:ce:5f:17', 'match': {'macaddress': '0e:ba:5e:ce:5f:17'}, 'subnets': [{'type': 'dhcp4'}]}
2021-08-13 17:06:52,594 - network_state.py[DEBUG]: v2_common: handling config:
{'eth0': {'dhcp4': True, 'dhcp6': False, 'match': {'macaddress': '0e:ba:5e:ce:5f:17'}, 'set-name': 'eth0'}}
2021-08-13 17:06:52,594 - netplan.py[DEBUG]: V2 to V2 passthrough
2021-08-13 17:06:52,595 - util.py[DEBUG]: Writing to /etc/netplan/50-cloud-init.yaml - wb: [644] 506 bytes
2021-08-13 17:06:52,596 - subp.py[DEBUG]: Running command ['netplan', 'generate'] with allowed return codes [0] (shell=False, capture=True)
2021-08-13 17:06:52,930 - subp.py[DEBUG]: Running command ['udevadm', 'test-builtin', 'net_setup_link', '/sys/class/net/eth0'] with allowed return codes [0] (shell=False, capture=True)
2021-08-13 17:06:52,941 - subp.py[DEBUG]: Running command ['udevadm', 'test-builtin', 'net_setup_link', '/sys/class/net/lo'] with allowed return codes [0] (shell=False, capture=True)
2021-08-13 17:06:52,950 - main.py[DEBUG]: [local] Exiting. datasource DataSourceEc2Local not in local mode.
2021-08-13 17:06:52,951 - atomic_helper.py[DEBUG]: Atomically writing to file /var/lib/cloud/data/status.json (via temporary file /var/lib/cloud/data/tmppdds4mo1) - w: [644] 491 bytes/chars
2021-08-13 17:06:52,951 - util.py[DEBUG]: Reading from /proc/uptime (quiet=False)
2021-08-13 17:06:52,951 - util.py[DEBUG]: Read 10 bytes from /proc/uptime
2021-08-13 17:06:52,952 - util.py[DEBUG]: cloud-init mode 'init' took 1.011 seconds (1.00)
2021-08-13 17:06:52,952 - handlers.py[DEBUG]: finish: init-local: SUCCESS: searching for local datasources
2021-08-13 17:06:55,418 - util.py[DEBUG]: Cloud-init v. 21.1-19-gbad84ad4-0ubuntu1~20.04.2 running 'init' at Fri, 13 Aug 2021 17:06:55 +0000. Up 10.62 seconds.
2021-08-13 17:06:55,418 - main.py[DEBUG]: No kernel command line url found.
2021-08-13 17:06:55,418 - main.py[DEBUG]: Closing stdin.
2021-08-13 17:06:55,420 - util.py[DEBUG]: Writing to /var/log/cloud-init.log - ab: [644] 0 bytes
2021-08-13 17:06:55,420 - util.py[DEBUG]: Changing the ownership of /var/log/cloud-init.log to 104:4
2021-08-13 17:06:55,421 - subp.py[DEBUG]: Running command ['ip', 'addr', 'show'] with allowed return codes [0] (shell=False, capture=True)
2021-08-13 17:06:55,425 - subp.py[DEBUG]: Running command ['ip', '-o', 'route', 'list'] with allowed return codes [0] (shell=False, capture=True)
2021-08-13 17:06:55,428 - subp.py[DEBUG]: Running command ['ip', '--oneline', '-6', 'route', 'list', 'table', 'all'] with allowed return codes [0, 1] (shell=False, capture=True)
2021-08-13 17:06:55,432 - main.py[DEBUG]: Checking to see if files that we need already exist from a previous run that would allow us to stop early.
2021-08-13 17:06:55,432 - main.py[DEBUG]: Execution continuing, no previous run detected that would allow us to stop early.
2021-08-13 17:06:55,433 - handlers.py[DEBUG]: start: init-network/check-cache: attempting to read from cache [trust]
2021-08-13 17:06:55,433 - util.py[DEBUG]: Reading from /var/lib/cloud/instance/obj.pkl (quiet=False)
2021-08-13 17:06:55,433 - util.py[DEBUG]: Read 11083 bytes from /var/lib/cloud/instance/obj.pkl
2021-08-13 17:06:55,436 - util.py[DEBUG]: Reading from /run/cloud-init/.instance-id (quiet=False)
2021-08-13 17:06:55,436 - util.py[DEBUG]: Read 20 bytes from /run/cloud-init/.instance-id
2021-08-13 17:06:55,436 - stages.py[DEBUG]: restored from cache with run check: DataSourceEc2Local
2021-08-13 17:06:55,436 - handlers.py[DEBUG]: finish: init-network/check-cache: SUCCESS: restored from cache with run check: DataSourceEc2Local
2021-08-13 17:06:55,436 - util.py[DEBUG]: Reading from /etc/cloud/cloud.cfg (quiet=False)
2021-08-13 17:06:55,436 - util.py[DEBUG]: Read 3619 bytes from /etc/cloud/cloud.cfg
2021-08-13 17:06:55,436 - util.py[DEBUG]: Attempting to load yaml from string of length 3619 with allowed root types (<class 'dict'>,)
2021-08-13 17:06:55,448 - util.py[DEBUG]: Reading from /etc/cloud/cloud.cfg.d/90_dpkg.cfg (quiet=False)
2021-08-13 17:06:55,448 - util.py[DEBUG]: Read 294 bytes from /etc/cloud/cloud.cfg.d/90_dpkg.cfg
2021-08-13 17:06:55,448 - util.py[DEBUG]: Attempting to load yaml from string of length 294 with allowed root types (<class 'dict'>,)
2021-08-13 17:06:55,450 - util.py[DEBUG]: Reading from /etc/cloud/cloud.cfg.d/05_logging.cfg (quiet=False)
2021-08-13 17:06:55,450 - util.py[DEBUG]: Read 2070 bytes from /etc/cloud/cloud.cfg.d/05_logging.cfg
2021-08-13 17:06:55,450 - util.py[DEBUG]: Attempting to load yaml from string of length 2070 with allowed root types (<class 'dict'>,)
2021-08-13 17:06:55,453 - util.py[DEBUG]: Reading from /run/cloud-init/cloud.cfg (quiet=False)
2021-08-13 17:06:55,453 - util.py[DEBUG]: Read 31 bytes from /run/cloud-init/cloud.cfg
2021-08-13 17:06:55,453 - util.py[DEBUG]: Attempting to load yaml from string of length 31 with allowed root types (<class 'dict'>,)
2021-08-13 17:06:55,454 - util.py[DEBUG]: Attempting to load yaml from string of length 0 with allowed root types (<class 'dict'>,)
2021-08-13 17:06:55,454 - util.py[DEBUG]: loaded blob returned None, returning default.
2021-08-13 17:06:55,454 - util.py[DEBUG]: Attempting to remove /var/lib/cloud/instance
2021-08-13 17:06:55,454 - util.py[DEBUG]: Creating symbolic link from '/var/lib/cloud/instance' => '/var/lib/cloud/instances/i-0d483f9ce23b7fccc'
2021-08-13 17:06:55,455 - util.py[DEBUG]: Reading from /var/lib/cloud/instances/i-0d483f9ce23b7fccc/datasource (quiet=False)
2021-08-13 17:06:55,455 - util.py[DEBUG]: Read 39 bytes from /var/lib/cloud/instances/i-0d483f9ce23b7fccc/datasource
2021-08-13 17:06:55,455 - util.py[DEBUG]: Writing to /var/lib/cloud/instances/i-0d483f9ce23b7fccc/datasource - wb: [644] 39 bytes
2021-08-13 17:06:55,455 - util.py[DEBUG]: Writing to /var/lib/cloud/data/previous-datasource - wb: [644] 39 bytes
2021-08-13 17:06:55,456 - util.py[DEBUG]: Reading from /var/lib/cloud/data/instance-id (quiet=False)
2021-08-13 17:06:55,456 - util.py[DEBUG]: Read 20 bytes from /var/lib/cloud/data/instance-id
2021-08-13 17:06:55,456 - stages.py[DEBUG]: previous iid found to be i-0d483f9ce23b7fccc
2021-08-13 17:06:55,456 - util.py[DEBUG]: Writing to /var/lib/cloud/data/instance-id - wb: [644] 20 bytes
2021-08-13 17:06:55,456 - util.py[DEBUG]: Writing to /run/cloud-init/.instance-id - wb: [644] 20 bytes
2021-08-13 17:06:55,457 - util.py[DEBUG]: Writing to /var/lib/cloud/data/previous-instance-id - wb: [644] 20 bytes
2021-08-13 17:06:55,457 - util.py[DEBUG]: Writing to /var/lib/cloud/instance/obj.pkl - wb: [400] 11086 bytes
2021-08-13 17:06:55,459 - main.py[DEBUG]: [net] init will now be targeting instance id: i-0d483f9ce23b7fccc. new=False
2021-08-13 17:06:55,459 - util.py[DEBUG]: Reading from /etc/cloud/cloud.cfg (quiet=False)
2021-08-13 17:06:55,459 - util.py[DEBUG]: Read 3619 bytes from /etc/cloud/cloud.cfg
2021-08-13 17:06:55,459 - util.py[DEBUG]: Attempting to load yaml from string of length 3619 with allowed root types (<class 'dict'>,)
2021-08-13 17:06:55,471 - util.py[DEBUG]: Reading from /etc/cloud/cloud.cfg.d/90_dpkg.cfg (quiet=False)
2021-08-13 17:06:55,471 - util.py[DEBUG]: Read 294 bytes from /etc/cloud/cloud.cfg.d/90_dpkg.cfg
2021-08-13 17:06:55,471 - util.py[DEBUG]: Attempting to load yaml from string of length 294 with allowed root types (<class 'dict'>,)
2021-08-13 17:06:55,473 - util.py[DEBUG]: Reading from /etc/cloud/cloud.cfg.d/05_logging.cfg (quiet=False)
2021-08-13 17:06:55,473 - util.py[DEBUG]: Read 2070 bytes from /etc/cloud/cloud.cfg.d/05_logging.cfg
2021-08-13 17:06:55,473 - util.py[DEBUG]: Attempting to load yaml from string of length 2070 with allowed root types (<class 'dict'>,)
2021-08-13 17:06:55,476 - util.py[DEBUG]: Reading from /run/cloud-init/cloud.cfg (quiet=False)
2021-08-13 17:06:55,477 - util.py[DEBUG]: Read 31 bytes from /run/cloud-init/cloud.cfg
2021-08-13 17:06:55,477 - util.py[DEBUG]: Attempting to load yaml from string of length 31 with allowed root types (<class 'dict'>,)
2021-08-13 17:06:55,477 - util.py[DEBUG]: Attempting to load yaml from string of length 0 with allowed root types (<class 'dict'>,)
2021-08-13 17:06:55,477 - util.py[DEBUG]: loaded blob returned None, returning default.
2021-08-13 17:06:55,478 - util.py[DEBUG]: Reading from /sys/class/net/eth0/address (quiet=False)
2021-08-13 17:06:55,478 - util.py[DEBUG]: Read 18 bytes from /sys/class/net/eth0/address
2021-08-13 17:06:55,478 - util.py[DEBUG]: Reading from /sys/class/net/lo/address (quiet=False)
2021-08-13 17:06:55,479 - util.py[DEBUG]: Read 18 bytes from /sys/class/net/lo/address
2021-08-13 17:06:55,479 - util.py[DEBUG]: Reading from /sys/class/net/eth0/addr_assign_type (quiet=False)
2021-08-13 17:06:55,479 - util.py[DEBUG]: Read 2 bytes from /sys/class/net/eth0/addr_assign_type
2021-08-13 17:06:55,479 - util.py[DEBUG]: Reading from /sys/class/net/eth0/uevent (quiet=False)
2021-08-13 17:06:55,479 - util.py[DEBUG]: Read 25 bytes from /sys/class/net/eth0/uevent
2021-08-13 17:06:55,479 - util.py[DEBUG]: Reading from /sys/class/net/eth0/address (quiet=False)
2021-08-13 17:06:55,479 - util.py[DEBUG]: Read 18 bytes from /sys/class/net/eth0/address
2021-08-13 17:06:55,479 - __init__.py[DEBUG]: ovs-vsctl not in PATH; not detecting Open vSwitch interfaces
2021-08-13 17:06:55,479 - util.py[DEBUG]: Reading from /sys/class/net/eth0/device/device (quiet=False)
2021-08-13 17:06:55,480 - util.py[DEBUG]: Reading from /sys/class/net/lo/addr_assign_type (quiet=False)
2021-08-13 17:06:55,480 - util.py[DEBUG]: Read 2 bytes from /sys/class/net/lo/addr_assign_type
2021-08-13 17:06:55,480 - util.py[DEBUG]: Reading from /sys/class/net/lo/uevent (quiet=False)
2021-08-13 17:06:55,480 - util.py[DEBUG]: Read 23 bytes from /sys/class/net/lo/uevent
2021-08-13 17:06:55,480 - util.py[DEBUG]: Reading from /sys/class/net/lo/address (quiet=False)
2021-08-13 17:06:55,480 - util.py[DEBUG]: Read 18 bytes from /sys/class/net/lo/address
2021-08-13 17:06:55,480 - util.py[DEBUG]: Reading from /sys/class/net/lo/device/device (quiet=False)
2021-08-13 17:06:55,480 - util.py[DEBUG]: Reading from /sys/class/net/eth0/type (quiet=False)
2021-08-13 17:06:55,480 - util.py[DEBUG]: Read 2 bytes from /sys/class/net/eth0/type
2021-08-13 17:06:55,480 - util.py[DEBUG]: Reading from /sys/class/net/lo/type (quiet=False)
2021-08-13 17:06:55,480 - util.py[DEBUG]: Read 4 bytes from /sys/class/net/lo/type
2021-08-13 17:06:55,480 - __init__.py[DEBUG]: Datasource DataSourceEc2Local not updated for events: System boot
2021-08-13 17:06:55,480 - stages.py[DEBUG]: No network config applied. Neither a new instance nor datasource network update on 'System boot' event
2021-08-13 17:06:55,480 - stages.py[DEBUG]: applying net config names for {'version': 2, 'ethernets': {'eth0': {'dhcp4': True, 'dhcp6': False, 'match': {'macaddress': '0e:ba:5e:ce:5f:17'}, 'set-name': 'eth0'}}}
2021-08-13 17:06:55,481 - stages.py[DEBUG]: Using distro class <class 'cloudinit.distros.ubuntu.Distro'>
2021-08-13 17:06:55,481 - util.py[DEBUG]: Reading from /sys/class/net/eth0/device/device (quiet=False)
2021-08-13 17:06:55,481 - util.py[DEBUG]: Reading from /sys/class/net/eth0/addr_assign_type (quiet=False)
2021-08-13 17:06:55,481 - util.py[DEBUG]: Read 2 bytes from /sys/class/net/eth0/addr_assign_type
2021-08-13 17:06:55,482 - util.py[DEBUG]: Reading from /sys/class/net/eth0/uevent (quiet=False)
2021-08-13 17:06:55,482 - util.py[DEBUG]: Read 25 bytes from /sys/class/net/eth0/uevent
2021-08-13 17:06:55,482 - util.py[DEBUG]: Reading from /sys/class/net/eth0/address (quiet=False)
2021-08-13 17:06:55,482 - util.py[DEBUG]: Read 18 bytes from /sys/class/net/eth0/address
2021-08-13 17:06:55,482 - util.py[DEBUG]: Reading from /sys/class/net/eth0/device/device (quiet=False)
2021-08-13 17:06:55,482 - util.py[DEBUG]: Reading from /sys/class/net/lo/addr_assign_type (quiet=False)
2021-08-13 17:06:55,482 - util.py[DEBUG]: Read 2 bytes from /sys/class/net/lo/addr_assign_type
2021-08-13 17:06:55,482 - util.py[DEBUG]: Reading from /sys/class/net/lo/uevent (quiet=False)
2021-08-13 17:06:55,482 - util.py[DEBUG]: Read 23 bytes from /sys/class/net/lo/uevent
2021-08-13 17:06:55,482 - util.py[DEBUG]: Reading from /sys/class/net/lo/address (quiet=False)
2021-08-13 17:06:55,482 - util.py[DEBUG]: Read 18 bytes from /sys/class/net/lo/address
2021-08-13 17:06:55,482 - util.py[DEBUG]: Reading from /sys/class/net/lo/device/device (quiet=False)
2021-08-13 17:06:55,482 - util.py[DEBUG]: Reading from /sys/class/net/eth0/operstate (quiet=False)
2021-08-13 17:06:55,482 - util.py[DEBUG]: Read 3 bytes from /sys/class/net/eth0/operstate
2021-08-13 17:06:55,483 - util.py[DEBUG]: Reading from /sys/class/net/lo/operstate (quiet=False)
2021-08-13 17:06:55,483 - util.py[DEBUG]: Read 8 bytes from /sys/class/net/lo/operstate
2021-08-13 17:06:55,483 - subp.py[DEBUG]: Running command ['ip', '-6', 'addr', 'show', 'permanent', 'scope', 'global'] with allowed return codes [0] (shell=False, capture=True)
2021-08-13 17:06:55,486 - subp.py[DEBUG]: Running command ['ip', '-4', 'addr', 'show'] with allowed return codes [0] (shell=False, capture=True)
2021-08-13 17:06:55,489 - __init__.py[DEBUG]: no work necessary for renaming of [['0e:ba:5e:ce:5f:17', 'eth0', 'vif', None]]
2021-08-13 17:06:55,489 - handlers.py[DEBUG]: start: init-network/setup-datasource: setting up datasource
2021-08-13 17:06:55,489 - handlers.py[DEBUG]: finish: init-network/setup-datasource: SUCCESS: setting up datasource
2021-08-13 17:06:55,489 - util.py[DEBUG]: Writing to /var/lib/cloud/instances/i-0d483f9ce23b7fccc/user-data.txt - wb: [600] 0 bytes
2021-08-13 17:06:55,492 - util.py[DEBUG]: Writing to /var/lib/cloud/instances/i-0d483f9ce23b7fccc/user-data.txt.i - wb: [600] 308 bytes
2021-08-13 17:06:55,493 - util.py[DEBUG]: Writing to /var/lib/cloud/instances/i-0d483f9ce23b7fccc/vendor-data.txt - wb: [600] 0 bytes
2021-08-13 17:06:55,494 - util.py[DEBUG]: Writing to /var/lib/cloud/instances/i-0d483f9ce23b7fccc/vendor-data.txt.i - wb: [600] 308 bytes
2021-08-13 17:06:55,494 - util.py[DEBUG]: Writing to /var/lib/cloud/instances/i-0d483f9ce23b7fccc/vendor-data2.txt - wb: [600] 0 bytes
2021-08-13 17:06:55,495 - util.py[DEBUG]: Writing to /var/lib/cloud/instances/i-0d483f9ce23b7fccc/vendor-data2.txt.i - wb: [600] 308 bytes
2021-08-13 17:06:55,496 - util.py[DEBUG]: Reading from /var/lib/cloud/data/set-hostname (quiet=False)
2021-08-13 17:06:55,496 - util.py[DEBUG]: Read 76 bytes from /var/lib/cloud/data/set-hostname
2021-08-13 17:06:55,496 - cc_set_hostname.py[DEBUG]: No hostname changes. Skipping set-hostname
2021-08-13 17:06:55,496 - util.py[DEBUG]: Writing to /var/lib/cloud/instances/i-0d483f9ce23b7fccc/sem/consume_data - wb: [644] 24 bytes
2021-08-13 17:06:55,497 - helpers.py[DEBUG]: Running consume_data using lock (<FileLock using file '/var/lib/cloud/instances/i-0d483f9ce23b7fccc/sem/consume_data'>)
2021-08-13 17:06:55,497 - handlers.py[DEBUG]: start: init-network/consume-user-data: reading and applying user-data
2021-08-13 17:06:55,497 - launch_index.py[DEBUG]: Discarding 0 multipart messages which do not match launch index 0
2021-08-13 17:06:55,498 - stages.py[DEBUG]: Added default handler for {'text/cloud-config', 'text/cloud-config-jsonp'} from CloudConfigPartHandler: [['text/cloud-config', 'text/cloud-config-jsonp']]
2021-08-13 17:06:55,498 - stages.py[DEBUG]: Added default handler for {'text/x-shellscript'} from ShellScriptPartHandler: [['text/x-shellscript']]
2021-08-13 17:06:55,498 - stages.py[DEBUG]: Added default handler for {'text/cloud-boothook'} from BootHookPartHandler: [['text/cloud-boothook']]
2021-08-13 17:06:55,498 - stages.py[DEBUG]: Added default handler for {'text/upstart-job'} from UpstartJobPartHandler: [['text/upstart-job']]
2021-08-13 17:06:55,498 - stages.py[DEBUG]: Added default handler for {'text/jinja2'} from JinjaTemplatePartHandler: [['text/jinja2']]
2021-08-13 17:06:55,498 - __init__.py[DEBUG]: Calling handler CloudConfigPartHandler: [['text/cloud-config', 'text/cloud-config-jsonp']] (__begin__, None, 3) with frequency once-per-instance
2021-08-13 17:06:55,498 - __init__.py[DEBUG]: Calling handler ShellScriptPartHandler: [['text/x-shellscript']] (__begin__, None, 2) with frequency once-per-instance
2021-08-13 17:06:55,498 - __init__.py[DEBUG]: Calling handler BootHookPartHandler: [['text/cloud-boothook']] (__begin__, None, 2) with frequency once-per-instance
2021-08-13 17:06:55,498 - __init__.py[DEBUG]: Calling handler UpstartJobPartHandler: [['text/upstart-job']] (__begin__, None, 2) with frequency once-per-instance
2021-08-13 17:06:55,498 - __init__.py[DEBUG]: Calling handler JinjaTemplatePartHandler: [['text/jinja2']] (__begin__, None, 3) with frequency once-per-instance
2021-08-13 17:06:55,498 - __init__.py[DEBUG]: {'MIME-Version': '1.0', 'Content-Type': 'text/x-not-multipart', 'Content-Disposition': 'attachment; filename="part-001"'}
2021-08-13 17:06:55,499 - __init__.py[DEBUG]: Empty payload of type text/x-not-multipart
2021-08-13 17:06:55,499 - __init__.py[DEBUG]: Calling handler CloudConfigPartHandler: [['text/cloud-config', 'text/cloud-config-jsonp']] (__end__, None, 3) with frequency once-per-instance
2021-08-13 17:06:55,499 - util.py[DEBUG]: Writing to /var/lib/cloud/instances/i-0d483f9ce23b7fccc/cloud-config.txt - wb: [600] 0 bytes
2021-08-13 17:06:55,499 - __init__.py[DEBUG]: Calling handler ShellScriptPartHandler: [['text/x-shellscript']] (__end__, None, 2) with frequency once-per-instance
2021-08-13 17:06:55,499 - __init__.py[DEBUG]: Calling handler BootHookPartHandler: [['text/cloud-boothook']] (__end__, None, 2) with frequency once-per-instance
2021-08-13 17:06:55,499 - __init__.py[DEBUG]: Calling handler UpstartJobPartHandler: [['text/upstart-job']] (__end__, None, 2) with frequency once-per-instance
2021-08-13 17:06:55,499 - __init__.py[DEBUG]: Calling handler JinjaTemplatePartHandler: [['text/jinja2']] (__end__, None, 3) with frequency once-per-instance
2021-08-13 17:06:55,499 - handlers.py[DEBUG]: finish: init-network/consume-user-data: SUCCESS: reading and applying user-data
2021-08-13 17:06:55,499 - handlers.py[DEBUG]: start: init-network/consume-vendor-data: reading and applying vendor-data
2021-08-13 17:06:55,500 - stages.py[DEBUG]: no vendordata from datasource
2021-08-13 17:06:55,500 - handlers.py[DEBUG]: finish: init-network/consume-vendor-data: SUCCESS: reading and applying vendor-data
2021-08-13 17:06:55,500 - handlers.py[DEBUG]: start: init-network/consume-vendor-data2: reading and applying vendor-data2
2021-08-13 17:06:55,500 - stages.py[DEBUG]: no vendordata2 from datasource
2021-08-13 17:06:55,500 - handlers.py[DEBUG]: finish: init-network/consume-vendor-data2: SUCCESS: reading and applying vendor-data2
2021-08-13 17:06:55,500 - util.py[DEBUG]: Reading from /etc/cloud/cloud.cfg (quiet=False)
2021-08-13 17:06:55,500 - util.py[DEBUG]: Read 3619 bytes from /etc/cloud/cloud.cfg
2021-08-13 17:06:55,500 - util.py[DEBUG]: Attempting to load yaml from string of length 3619 with allowed root types (<class 'dict'>,)
2021-08-13 17:06:55,512 - util.py[DEBUG]: Reading from /etc/cloud/cloud.cfg.d/90_dpkg.cfg (quiet=False)
2021-08-13 17:06:55,512 - util.py[DEBUG]: Read 294 bytes from /etc/cloud/cloud.cfg.d/90_dpkg.cfg
2021-08-13 17:06:55,512 - util.py[DEBUG]: Attempting to load yaml from string of length 294 with allowed root types (<class 'dict'>,)
2021-08-13 17:06:55,514 - util.py[DEBUG]: Reading from /etc/cloud/cloud.cfg.d/05_logging.cfg (quiet=False)
2021-08-13 17:06:55,514 - util.py[DEBUG]: Read 2070 bytes from /etc/cloud/cloud.cfg.d/05_logging.cfg
2021-08-13 17:06:55,514 - util.py[DEBUG]: Attempting to load yaml from string of length 2070 with allowed root types (<class 'dict'>,)
2021-08-13 17:06:55,517 - util.py[DEBUG]: Reading from /run/cloud-init/cloud.cfg (quiet=False)
2021-08-13 17:06:55,517 - util.py[DEBUG]: Read 31 bytes from /run/cloud-init/cloud.cfg
2021-08-13 17:06:55,517 - util.py[DEBUG]: Attempting to load yaml from string of length 31 with allowed root types (<class 'dict'>,)
2021-08-13 17:06:55,518 - util.py[DEBUG]: Attempting to load yaml from string of length 0 with allowed root types (<class 'dict'>,)
2021-08-13 17:06:55,518 - util.py[DEBUG]: loaded blob returned None, returning default.
2021-08-13 17:06:55,518 - util.py[DEBUG]: Reading from /var/lib/cloud/instance/cloud-config.txt (quiet=False)
2021-08-13 17:06:55,518 - util.py[DEBUG]: Read 0 bytes from /var/lib/cloud/instance/cloud-config.txt
2021-08-13 17:06:55,518 - util.py[DEBUG]: Attempting to load yaml from string of length 0 with allowed root types (<class 'dict'>,)
2021-08-13 17:06:55,518 - util.py[DEBUG]: loaded blob returned None, returning default.
2021-08-13 17:06:55,519 - util.py[DEBUG]: Reading from /var/lib/cloud/instance/cloud-config.txt (quiet=False)
2021-08-13 17:06:55,519 - util.py[DEBUG]: Read 0 bytes from /var/lib/cloud/instance/cloud-config.txt
2021-08-13 17:06:55,519 - util.py[DEBUG]: Attempting to load yaml from string of length 0 with allowed root types (<class 'dict'>,)
2021-08-13 17:06:55,519 - util.py[DEBUG]: loaded blob returned None, returning default.
2021-08-13 17:06:55,529 - handlers.py[DEBUG]: start: init-network/activate-datasource: activating datasource
2021-08-13 17:06:55,530 - util.py[DEBUG]: Writing to /var/lib/cloud/instance/obj.pkl - wb: [400] 13332 bytes
2021-08-13 17:06:55,533 - handlers.py[DEBUG]: finish: init-network/activate-datasource: SUCCESS: activating datasource
2021-08-13 17:06:55,533 - main.py[DEBUG]: no di_report found in config.
2021-08-13 17:06:55,573 - stages.py[DEBUG]: Using distro class <class 'cloudinit.distros.ubuntu.Distro'>
2021-08-13 17:06:55,573 - stages.py[DEBUG]: Running module migrator (<module 'cloudinit.config.cc_migrator' from '/usr/lib/python3/dist-packages/cloudinit/config/cc_migrator.py'>) with frequency always
2021-08-13 17:06:55,574 - handlers.py[DEBUG]: start: init-network/config-migrator: running config-migrator with frequency always
2021-08-13 17:06:55,574 - helpers.py[DEBUG]: Running config-migrator using lock (<cloudinit.helpers.DummyLock object at 0x7fb35c97de20>)
2021-08-13 17:06:55,574 - cc_migrator.py[DEBUG]: Migrated 0 semaphore files to there canonicalized names
2021-08-13 17:06:55,574 - handlers.py[DEBUG]: finish: init-network/config-migrator: SUCCESS: config-migrator ran successfully
2021-08-13 17:06:55,574 - stages.py[DEBUG]: Running module seed_random (<module 'cloudinit.config.cc_seed_random' from '/usr/lib/python3/dist-packages/cloudinit/config/cc_seed_random.py'>) with frequency once-per-instance
2021-08-13 17:06:55,574 - handlers.py[DEBUG]: start: init-network/config-seed_random: running config-seed_random with frequency once-per-instance
2021-08-13 17:06:55,574 - util.py[DEBUG]: Writing to /var/lib/cloud/instances/i-0d483f9ce23b7fccc/sem/config_seed_random - wb: [644] 24 bytes
2021-08-13 17:06:55,575 - helpers.py[DEBUG]: Running config-seed_random using lock (<FileLock using file '/var/lib/cloud/instances/i-0d483f9ce23b7fccc/sem/config_seed_random'>)
2021-08-13 17:06:55,575 - cc_seed_random.py[DEBUG]: no command provided
2021-08-13 17:06:55,575 - handlers.py[DEBUG]: finish: init-network/config-seed_random: SUCCESS: config-seed_random ran successfully
2021-08-13 17:06:55,575 - stages.py[DEBUG]: Running module bootcmd (<module 'cloudinit.config.cc_bootcmd' from '/usr/lib/python3/dist-packages/cloudinit/config/cc_bootcmd.py'>) with frequency always
2021-08-13 17:06:55,575 - handlers.py[DEBUG]: start: init-network/config-bootcmd: running config-bootcmd with frequency always
2021-08-13 17:06:55,575 - helpers.py[DEBUG]: Running config-bootcmd using lock (<cloudinit.helpers.DummyLock object at 0x7fb35c97db20>)
2021-08-13 17:06:55,575 - cc_bootcmd.py[DEBUG]: Skipping module named bootcmd, no 'bootcmd' key in configuration
2021-08-13 17:06:55,575 - handlers.py[DEBUG]: finish: init-network/config-bootcmd: SUCCESS: config-bootcmd ran successfully
2021-08-13 17:06:55,575 - stages.py[DEBUG]: Running module write-files (<module 'cloudinit.config.cc_write_files' from '/usr/lib/python3/dist-packages/cloudinit/config/cc_write_files.py'>) with frequency once-per-instance
2021-08-13 17:06:55,576 - handlers.py[DEBUG]: start: init-network/config-write-files: running config-write-files with frequency once-per-instance
2021-08-13 17:06:55,576 - util.py[DEBUG]: Writing to /var/lib/cloud/instances/i-0d483f9ce23b7fccc/sem/config_write_files - wb: [644] 24 bytes
2021-08-13 17:06:55,576 - helpers.py[DEBUG]: Running config-write-files using lock (<FileLock using file '/var/lib/cloud/instances/i-0d483f9ce23b7fccc/sem/config_write_files'>)
2021-08-13 17:06:55,576 - cc_write_files.py[DEBUG]: Skipping module named write-files, no/empty 'write_files' key in configuration
2021-08-13 17:06:55,576 - handlers.py[DEBUG]: finish: init-network/config-write-files: SUCCESS: config-write-files ran successfully
2021-08-13 17:06:55,576 - stages.py[DEBUG]: Running module growpart (<module 'cloudinit.config.cc_growpart' from '/usr/lib/python3/dist-packages/cloudinit/config/cc_growpart.py'>) with frequency always
2021-08-13 17:06:55,577 - handlers.py[DEBUG]: start: init-network/config-growpart: running config-growpart with frequency always
2021-08-13 17:06:55,577 - helpers.py[DEBUG]: Running config-growpart using lock (<cloudinit.helpers.DummyLock object at 0x7fb35c97de20>)
2021-08-13 17:06:55,577 - cc_growpart.py[DEBUG]: No 'growpart' entry in cfg.  Using default: {'mode': 'auto', 'devices': ['/'], 'ignore_growroot_disabled': False}
2021-08-13 17:06:55,577 - subp.py[DEBUG]: Running command ['growpart', '--help'] with allowed return codes [0] (shell=False, capture=True)
2021-08-13 17:06:55,588 - util.py[DEBUG]: Reading from /proc/381/mountinfo (quiet=False)
2021-08-13 17:06:55,589 - util.py[DEBUG]: Read 3469 bytes from /proc/381/mountinfo
2021-08-13 17:06:55,589 - util.py[DEBUG]: Reading from /sys/class/block/xvda1/partition (quiet=False)
2021-08-13 17:06:55,589 - util.py[DEBUG]: Read 2 bytes from /sys/class/block/xvda1/partition
2021-08-13 17:06:55,589 - util.py[DEBUG]: Reading from /sys/devices/vbd-768/block/xvda/dev (quiet=False)
2021-08-13 17:06:55,589 - util.py[DEBUG]: Read 6 bytes from /sys/devices/vbd-768/block/xvda/dev
2021-08-13 17:06:55,589 - subp.py[DEBUG]: Running command ['growpart', '--dry-run', '/dev/xvda', '1'] with allowed return codes [0] (shell=False, capture=True)
2021-08-13 17:06:55,713 - util.py[DEBUG]: resize_devices took 0.125 seconds
2021-08-13 17:06:55,713 - cc_growpart.py[DEBUG]: '/' NOCHANGE: no change necessary (/dev/xvda, 1)
2021-08-13 17:06:55,714 - handlers.py[DEBUG]: finish: init-network/config-growpart: SUCCESS: config-growpart ran successfully
2021-08-13 17:06:55,714 - stages.py[DEBUG]: Running module resizefs (<module 'cloudinit.config.cc_resizefs' from '/usr/lib/python3/dist-packages/cloudinit/config/cc_resizefs.py'>) with frequency always
2021-08-13 17:06:55,714 - handlers.py[DEBUG]: start: init-network/config-resizefs: running config-resizefs with frequency always
2021-08-13 17:06:55,714 - helpers.py[DEBUG]: Running config-resizefs using lock (<cloudinit.helpers.DummyLock object at 0x7fb35c97dc70>)
2021-08-13 17:06:55,797 - util.py[DEBUG]: Reading from /proc/381/mountinfo (quiet=False)
2021-08-13 17:06:55,797 - util.py[DEBUG]: Read 3469 bytes from /proc/381/mountinfo
2021-08-13 17:06:55,798 - cc_resizefs.py[DEBUG]: resize_info: dev=/dev/root mnt_point=/ path=/
2021-08-13 17:06:55,798 - cc_resizefs.py[DEBUG]: Resizing / (ext4) using resize2fs /dev/root
2021-08-13 17:06:55,798 - subp.py[DEBUG]: Running command ('resize2fs', '/dev/root') with allowed return codes [0] (shell=False, capture=True)
2021-08-13 17:06:55,811 - util.py[DEBUG]: Resizing took 0.013 seconds
2021-08-13 17:06:55,811 - cc_resizefs.py[DEBUG]: Resized root filesystem (type=ext4, val=True)
2021-08-13 17:06:55,812 - handlers.py[DEBUG]: finish: init-network/config-resizefs: SUCCESS: config-resizefs ran successfully
2021-08-13 17:06:55,812 - stages.py[DEBUG]: Running module disk_setup (<module 'cloudinit.config.cc_disk_setup' from '/usr/lib/python3/dist-packages/cloudinit/config/cc_disk_setup.py'>) with frequency once-per-instance
2021-08-13 17:06:55,812 - handlers.py[DEBUG]: start: init-network/config-disk_setup: running config-disk_setup with frequency once-per-instance
2021-08-13 17:06:55,812 - util.py[DEBUG]: Writing to /var/lib/cloud/instances/i-0d483f9ce23b7fccc/sem/config_disk_setup - wb: [644] 24 bytes
2021-08-13 17:06:55,813 - helpers.py[DEBUG]: Running config-disk_setup using lock (<FileLock using file '/var/lib/cloud/instances/i-0d483f9ce23b7fccc/sem/config_disk_setup'>)
2021-08-13 17:06:55,813 - handlers.py[DEBUG]: finish: init-network/config-disk_setup: SUCCESS: config-disk_setup ran successfully
2021-08-13 17:06:55,813 - stages.py[DEBUG]: Running module mounts (<module 'cloudinit.config.cc_mounts' from '/usr/lib/python3/dist-packages/cloudinit/config/cc_mounts.py'>) with frequency once-per-instance
2021-08-13 17:06:55,813 - handlers.py[DEBUG]: start: init-network/config-mounts: running config-mounts with frequency once-per-instance
2021-08-13 17:06:55,813 - util.py[DEBUG]: Writing to /var/lib/cloud/instances/i-0d483f9ce23b7fccc/sem/config_mounts - wb: [644] 24 bytes
2021-08-13 17:06:55,814 - helpers.py[DEBUG]: Running config-mounts using lock (<FileLock using file '/var/lib/cloud/instances/i-0d483f9ce23b7fccc/sem/config_mounts'>)
2021-08-13 17:06:55,814 - cc_mounts.py[DEBUG]: mounts configuration is []
2021-08-13 17:06:55,814 - util.py[DEBUG]: Reading from /etc/fstab (quiet=False)
2021-08-13 17:06:55,814 - util.py[DEBUG]: Read 51 bytes from /etc/fstab
2021-08-13 17:06:55,814 - cc_mounts.py[DEBUG]: Attempting to determine the real name of ephemeral0
2021-08-13 17:06:55,814 - DataSourceEc2.py[DEBUG]: Unable to convert ephemeral0 to a device
2021-08-13 17:06:55,814 - cc_mounts.py[DEBUG]: changed default device ephemeral0 => None
2021-08-13 17:06:55,814 - cc_mounts.py[DEBUG]: Ignoring nonexistent default named mount ephemeral0
2021-08-13 17:06:55,814 - cc_mounts.py[DEBUG]: Attempting to determine the real name of swap
2021-08-13 17:06:55,814 - DataSourceEc2.py[DEBUG]: Unable to convert swap to a device
2021-08-13 17:06:55,815 - cc_mounts.py[DEBUG]: changed default device swap => None
2021-08-13 17:06:55,815 - cc_mounts.py[DEBUG]: Ignoring nonexistent default named mount swap
2021-08-13 17:06:55,815 - cc_mounts.py[DEBUG]: no need to setup swap
2021-08-13 17:06:55,815 - cc_mounts.py[DEBUG]: No modifications to fstab needed
2021-08-13 17:06:55,815 - handlers.py[DEBUG]: finish: init-network/config-mounts: SUCCESS: config-mounts ran successfully
2021-08-13 17:06:55,815 - stages.py[DEBUG]: Running module set_hostname (<module 'cloudinit.config.cc_set_hostname' from '/usr/lib/python3/dist-packages/cloudinit/config/cc_set_hostname.py'>) with frequency once-per-instance
2021-08-13 17:06:55,831 - handlers.py[DEBUG]: start: init-network/config-set_hostname: running config-set_hostname with frequency once-per-instance
2021-08-13 17:06:55,831 - util.py[DEBUG]: Writing to /var/lib/cloud/instances/i-0d483f9ce23b7fccc/sem/config_set_hostname - wb: [644] 24 bytes
2021-08-13 17:06:55,832 - helpers.py[DEBUG]: Running config-set_hostname using lock (<FileLock using file '/var/lib/cloud/instances/i-0d483f9ce23b7fccc/sem/config_set_hostname'>)
2021-08-13 17:06:55,832 - util.py[DEBUG]: Reading from /var/lib/cloud/data/set-hostname (quiet=False)
2021-08-13 17:06:55,832 - util.py[DEBUG]: Read 76 bytes from /var/lib/cloud/data/set-hostname
2021-08-13 17:06:55,832 - cc_set_hostname.py[DEBUG]: No hostname changes. Skipping set-hostname
2021-08-13 17:06:55,832 - handlers.py[DEBUG]: finish: init-network/config-set_hostname: SUCCESS: config-set_hostname ran successfully
2021-08-13 17:06:55,832 - stages.py[DEBUG]: Running module update_hostname (<module 'cloudinit.config.cc_update_hostname' from '/usr/lib/python3/dist-packages/cloudinit/config/cc_update_hostname.py'>) with frequency always
2021-08-13 17:06:55,832 - handlers.py[DEBUG]: start: init-network/config-update_hostname: running config-update_hostname with frequency always
2021-08-13 17:06:55,832 - helpers.py[DEBUG]: Running config-update_hostname using lock (<cloudinit.helpers.DummyLock object at 0x7fb35c97de20>)
2021-08-13 17:06:55,832 - cc_update_hostname.py[DEBUG]: Updating hostname to ip-172-31-42-60.ec2.internal (ip-172-31-42-60)
2021-08-13 17:06:55,832 - util.py[DEBUG]: Reading from /etc/hostname (quiet=False)
2021-08-13 17:06:55,833 - util.py[DEBUG]: Read 16 bytes from /etc/hostname
2021-08-13 17:06:55,833 - __init__.py[DEBUG]: Attempting to update hostname to ip-172-31-42-60 in 1 files
2021-08-13 17:06:55,833 - util.py[DEBUG]: Reading from /var/lib/cloud/data/previous-hostname (quiet=False)
2021-08-13 17:06:55,833 - util.py[DEBUG]: Writing to /var/lib/cloud/data/previous-hostname - wb: [644] 16 bytes
2021-08-13 17:06:55,833 - handlers.py[DEBUG]: finish: init-network/config-update_hostname: SUCCESS: config-update_hostname ran successfully
2021-08-13 17:06:55,833 - stages.py[DEBUG]: Running module update_etc_hosts (<module 'cloudinit.config.cc_update_etc_hosts' from '/usr/lib/python3/dist-packages/cloudinit/config/cc_update_etc_hosts.py'>) with frequency always
2021-08-13 17:06:55,833 - handlers.py[DEBUG]: start: init-network/config-update_etc_hosts: running config-update_etc_hosts with frequency always
2021-08-13 17:06:55,833 - helpers.py[DEBUG]: Running config-update_etc_hosts using lock (<cloudinit.helpers.DummyLock object at 0x7fb35c97d160>)
2021-08-13 17:06:55,834 - cc_update_etc_hosts.py[DEBUG]: Configuration option 'manage_etc_hosts' is not set, not managing /etc/hosts in module update_etc_hosts
2021-08-13 17:06:55,834 - handlers.py[DEBUG]: finish: init-network/config-update_etc_hosts: SUCCESS: config-update_etc_hosts ran successfully
2021-08-13 17:06:55,834 - stages.py[DEBUG]: Running module ca-certs (<module 'cloudinit.config.cc_ca_certs' from '/usr/lib/python3/dist-packages/cloudinit/config/cc_ca_certs.py'>) with frequency once-per-instance
2021-08-13 17:06:55,834 - handlers.py[DEBUG]: start: init-network/config-ca-certs: running config-ca-certs with frequency once-per-instance
2021-08-13 17:06:55,834 - util.py[DEBUG]: Writing to /var/lib/cloud/instances/i-0d483f9ce23b7fccc/sem/config_ca_certs - wb: [644] 23 bytes
2021-08-13 17:06:55,834 - helpers.py[DEBUG]: Running config-ca-certs using lock (<FileLock using file '/var/lib/cloud/instances/i-0d483f9ce23b7fccc/sem/config_ca_certs'>)
2021-08-13 17:06:55,834 - cc_ca_certs.py[DEBUG]: Skipping module named ca-certs, no 'ca-certs' key in configuration
2021-08-13 17:06:55,834 - handlers.py[DEBUG]: finish: init-network/config-ca-certs: SUCCESS: config-ca-certs ran successfully
2021-08-13 17:06:55,835 - stages.py[DEBUG]: Running module rsyslog (<module 'cloudinit.config.cc_rsyslog' from '/usr/lib/python3/dist-packages/cloudinit/config/cc_rsyslog.py'>) with frequency once-per-instance
2021-08-13 17:06:55,835 - handlers.py[DEBUG]: start: init-network/config-rsyslog: running config-rsyslog with frequency once-per-instance
2021-08-13 17:06:55,835 - util.py[DEBUG]: Writing to /var/lib/cloud/instances/i-0d483f9ce23b7fccc/sem/config_rsyslog - wb: [644] 24 bytes
2021-08-13 17:06:55,835 - helpers.py[DEBUG]: Running config-rsyslog using lock (<FileLock using file '/var/lib/cloud/instances/i-0d483f9ce23b7fccc/sem/config_rsyslog'>)
2021-08-13 17:06:55,835 - cc_rsyslog.py[DEBUG]: Skipping module named rsyslog, no 'rsyslog' key in configuration
2021-08-13 17:06:55,835 - handlers.py[DEBUG]: finish: init-network/config-rsyslog: SUCCESS: config-rsyslog ran successfully
2021-08-13 17:06:55,835 - stages.py[DEBUG]: Running module users-groups (<module 'cloudinit.config.cc_users_groups' from '/usr/lib/python3/dist-packages/cloudinit/config/cc_users_groups.py'>) with frequency once-per-instance
2021-08-13 17:06:55,836 - handlers.py[DEBUG]: start: init-network/config-users-groups: running config-users-groups with frequency once-per-instance
2021-08-13 17:06:55,836 - util.py[DEBUG]: Writing to /var/lib/cloud/instances/i-0d483f9ce23b7fccc/sem/config_users_groups - wb: [644] 24 bytes
2021-08-13 17:06:55,836 - helpers.py[DEBUG]: Running config-users-groups using lock (<FileLock using file '/var/lib/cloud/instances/i-0d483f9ce23b7fccc/sem/config_users_groups'>)
2021-08-13 17:06:55,838 - util.py[DEBUG]: Reading from /etc/os-release (quiet=True)
2021-08-13 17:06:55,838 - util.py[DEBUG]: Read 382 bytes from /etc/os-release
2021-08-13 17:06:55,838 - util.py[DEBUG]: Reading from /etc/system-image/channel.ini (quiet=True)
2021-08-13 17:06:55,838 - util.py[DEBUG]: Read 0 bytes from /etc/system-image/channel.ini
2021-08-13 17:06:55,839 - __init__.py[DEBUG]: Adding user ubuntu
2021-08-13 17:06:55,839 - subp.py[DEBUG]: Running hidden command to protect sensitive input/output logstring: ['useradd', 'ubuntu', '--comment', 'Ubuntu', '--groups', 'adm,audio,cdrom,dialout,dip,floppy,lxd,netdev,plugdev,sudo,video', '--shell', '/bin/bash', '-m']
2021-08-13 17:06:55,957 - subp.py[DEBUG]: Running command ['passwd', '-l', 'ubuntu'] with allowed return codes [0] (shell=False, capture=True)
2021-08-13 17:06:55,977 - util.py[DEBUG]: Reading from /etc/sudoers (quiet=False)
2021-08-13 17:06:55,978 - util.py[DEBUG]: Read 755 bytes from /etc/sudoers
2021-08-13 17:06:55,979 - util.py[DEBUG]: Writing to /etc/sudoers.d/90-cloud-init-users - wb: [440] 152 bytes
2021-08-13 17:06:55,980 - handlers.py[DEBUG]: finish: init-network/config-users-groups: SUCCESS: config-users-groups ran successfully
2021-08-13 17:06:55,980 - stages.py[DEBUG]: Running module ssh (<module 'cloudinit.config.cc_ssh' from '/usr/lib/python3/dist-packages/cloudinit/config/cc_ssh.py'>) with frequency once-per-instance
2021-08-13 17:06:55,980 - handlers.py[DEBUG]: start: init-network/config-ssh: running config-ssh with frequency once-per-instance
2021-08-13 17:06:55,980 - util.py[DEBUG]: Writing to /var/lib/cloud/instances/i-0d483f9ce23b7fccc/sem/config_ssh - wb: [644] 24 bytes
2021-08-13 17:06:55,981 - helpers.py[DEBUG]: Running config-ssh using lock (<FileLock using file '/var/lib/cloud/instances/i-0d483f9ce23b7fccc/sem/config_ssh'>)
2021-08-13 17:06:55,982 - subp.py[DEBUG]: Running command ['ssh-keygen', '-t', 'rsa', '-N', '', '-f', '/etc/ssh/ssh_host_rsa_key'] with allowed return codes [0] (shell=False, capture=True)
2021-08-13 17:06:56,067 - subp.py[DEBUG]: Running command ['ssh-keygen', '-t', 'dsa', '-N', '', '-f', '/etc/ssh/ssh_host_dsa_key'] with allowed return codes [0] (shell=False, capture=True)
2021-08-13 17:06:56,143 - subp.py[DEBUG]: Running command ['ssh-keygen', '-t', 'ecdsa', '-N', '', '-f', '/etc/ssh/ssh_host_ecdsa_key'] with allowed return codes [0] (shell=False, capture=True)
2021-08-13 17:06:56,150 - subp.py[DEBUG]: Running command ['ssh-keygen', '-t', 'ed25519', '-N', '', '-f', '/etc/ssh/ssh_host_ed25519_key'] with allowed return codes [0] (shell=False, capture=True)
2021-08-13 17:06:56,157 - util.py[DEBUG]: Reading from /etc/ssh/ssh_host_rsa_key.pub (quiet=False)
2021-08-13 17:06:56,157 - util.py[DEBUG]: Read 574 bytes from /etc/ssh/ssh_host_rsa_key.pub
2021-08-13 17:06:56,157 - util.py[DEBUG]: Reading from /etc/ssh/ssh_host_ed25519_key.pub (quiet=False)
2021-08-13 17:06:56,157 - util.py[DEBUG]: Read 102 bytes from /etc/ssh/ssh_host_ed25519_key.pub
2021-08-13 17:06:56,157 - util.py[DEBUG]: Reading from /etc/ssh/ssh_host_ecdsa_key.pub (quiet=False)
2021-08-13 17:06:56,157 - util.py[DEBUG]: Read 182 bytes from /etc/ssh/ssh_host_ecdsa_key.pub
2021-08-13 17:06:56,158 - util.py[DEBUG]: Changing the ownership of /home/ubuntu/.ssh to 1000:1000
2021-08-13 17:06:56,159 - util.py[DEBUG]: Reading from /etc/ssh/sshd_config (quiet=False)
2021-08-13 17:06:56,159 - util.py[DEBUG]: Read 3287 bytes from /etc/ssh/sshd_config
2021-08-13 17:06:56,160 - util.py[DEBUG]: Writing to /home/ubuntu/.ssh/authorized_keys - wb: [600] 388 bytes
2021-08-13 17:06:56,160 - util.py[DEBUG]: Changing the ownership of /home/ubuntu/.ssh/authorized_keys to 1000:1000
2021-08-13 17:06:56,160 - util.py[DEBUG]: Changing the ownership of /root/.ssh to 0:0
2021-08-13 17:06:56,161 - util.py[DEBUG]: Reading from /etc/ssh/sshd_config (quiet=False)
2021-08-13 17:06:56,161 - util.py[DEBUG]: Read 3287 bytes from /etc/ssh/sshd_config
2021-08-13 17:06:56,161 - util.py[DEBUG]: Writing to /root/.ssh/authorized_keys - wb: [600] 552 bytes
2021-08-13 17:06:56,162 - util.py[DEBUG]: Changing the ownership of /root/.ssh/authorized_keys to 0:0
2021-08-13 17:06:56,162 - handlers.py[DEBUG]: finish: init-network/config-ssh: SUCCESS: config-ssh ran successfully
2021-08-13 17:06:56,162 - main.py[DEBUG]: Ran 15 modules with 0 failures
2021-08-13 17:06:56,163 - atomic_helper.py[DEBUG]: Atomically writing to file /var/lib/cloud/data/status.json (via temporary file /var/lib/cloud/data/tmps6p1osa2) - w: [644] 518 bytes/chars
2021-08-13 17:06:56,163 - util.py[DEBUG]: Reading from /proc/uptime (quiet=False)
2021-08-13 17:06:56,163 - util.py[DEBUG]: Read 11 bytes from /proc/uptime
2021-08-13 17:06:56,163 - util.py[DEBUG]: cloud-init mode 'init' took 0.792 seconds (0.79)
2021-08-13 17:06:56,163 - handlers.py[DEBUG]: finish: init-network: SUCCESS: searching for network datasources
2021-08-13 17:07:06,990 - util.py[DEBUG]: Cloud-init v. 21.1-19-gbad84ad4-0ubuntu1~20.04.2 running 'modules:config' at Fri, 13 Aug 2021 17:07:06 +0000. Up 22.09 seconds.
2021-08-13 17:07:07,029 - stages.py[DEBUG]: Using distro class <class 'cloudinit.distros.ubuntu.Distro'>
2021-08-13 17:07:07,030 - stages.py[DEBUG]: Running module emit_upstart (<module 'cloudinit.config.cc_emit_upstart' from '/usr/lib/python3/dist-packages/cloudinit/config/cc_emit_upstart.py'>) with frequency always
2021-08-13 17:07:07,030 - handlers.py[DEBUG]: start: modules-config/config-emit_upstart: running config-emit_upstart with frequency always
2021-08-13 17:07:07,030 - helpers.py[DEBUG]: Running config-emit_upstart using lock (<cloudinit.helpers.DummyLock object at 0x7f8b054acb80>)
2021-08-13 17:07:07,030 - cc_emit_upstart.py[DEBUG]: no /sbin/initctl located
2021-08-13 17:07:07,030 - cc_emit_upstart.py[DEBUG]: not upstart system, 'emit_upstart' disabled
2021-08-13 17:07:07,031 - handlers.py[DEBUG]: finish: modules-config/config-emit_upstart: SUCCESS: config-emit_upstart ran successfully
2021-08-13 17:07:07,031 - stages.py[DEBUG]: Running module snap (<module 'cloudinit.config.cc_snap' from '/usr/lib/python3/dist-packages/cloudinit/config/cc_snap.py'>) with frequency once-per-instance
2021-08-13 17:07:07,031 - handlers.py[DEBUG]: start: modules-config/config-snap: running config-snap with frequency once-per-instance
2021-08-13 17:07:07,031 - util.py[DEBUG]: Writing to /var/lib/cloud/instances/i-0d483f9ce23b7fccc/sem/config_snap - wb: [644] 25 bytes
2021-08-13 17:07:07,031 - helpers.py[DEBUG]: Running config-snap using lock (<FileLock using file '/var/lib/cloud/instances/i-0d483f9ce23b7fccc/sem/config_snap'>)
2021-08-13 17:07:07,031 - cc_snap.py[DEBUG]: Skipping module named snap, no 'snap' key in configuration
2021-08-13 17:07:07,031 - handlers.py[DEBUG]: finish: modules-config/config-snap: SUCCESS: config-snap ran successfully
2021-08-13 17:07:07,032 - stages.py[DEBUG]: Running module ssh-import-id (<module 'cloudinit.config.cc_ssh_import_id' from '/usr/lib/python3/dist-packages/cloudinit/config/cc_ssh_import_id.py'>) with frequency once-per-instance
2021-08-13 17:07:07,032 - handlers.py[DEBUG]: start: modules-config/config-ssh-import-id: running config-ssh-import-id with frequency once-per-instance
2021-08-13 17:07:07,032 - util.py[DEBUG]: Writing to /var/lib/cloud/instances/i-0d483f9ce23b7fccc/sem/config_ssh_import_id - wb: [644] 25 bytes
2021-08-13 17:07:07,032 - helpers.py[DEBUG]: Running config-ssh-import-id using lock (<FileLock using file '/var/lib/cloud/instances/i-0d483f9ce23b7fccc/sem/config_ssh_import_id'>)
2021-08-13 17:07:07,032 - handlers.py[DEBUG]: finish: modules-config/config-ssh-import-id: SUCCESS: config-ssh-import-id ran successfully
2021-08-13 17:07:07,033 - stages.py[DEBUG]: Running module locale (<module 'cloudinit.config.cc_locale' from '/usr/lib/python3/dist-packages/cloudinit/config/cc_locale.py'>) with frequency once-per-instance
2021-08-13 17:07:07,033 - handlers.py[DEBUG]: start: modules-config/config-locale: running config-locale with frequency once-per-instance
2021-08-13 17:07:07,033 - util.py[DEBUG]: Writing to /var/lib/cloud/instances/i-0d483f9ce23b7fccc/sem/config_locale - wb: [644] 25 bytes
2021-08-13 17:07:07,033 - helpers.py[DEBUG]: Running config-locale using lock (<FileLock using file '/var/lib/cloud/instances/i-0d483f9ce23b7fccc/sem/config_locale'>)
2021-08-13 17:07:07,033 - util.py[DEBUG]: Reading from /etc/default/locale (quiet=False)
2021-08-13 17:07:07,033 - util.py[DEBUG]: Read 13 bytes from /etc/default/locale
2021-08-13 17:07:07,061 - cc_locale.py[DEBUG]: Setting locale to C.UTF-8
2021-08-13 17:07:07,061 - debian.py[DEBUG]: System has 'LANG=C.UTF-8' requested 'C.UTF-8', skipping regeneration.
2021-08-13 17:07:07,061 - handlers.py[DEBUG]: finish: modules-config/config-locale: SUCCESS: config-locale ran successfully
2021-08-13 17:07:07,062 - stages.py[DEBUG]: Running module set-passwords (<module 'cloudinit.config.cc_set_passwords' from '/usr/lib/python3/dist-packages/cloudinit/config/cc_set_passwords.py'>) with frequency once-per-instance
2021-08-13 17:07:07,062 - handlers.py[DEBUG]: start: modules-config/config-set-passwords: running config-set-passwords with frequency once-per-instance
2021-08-13 17:07:07,062 - util.py[DEBUG]: Writing to /var/lib/cloud/instances/i-0d483f9ce23b7fccc/sem/config_set_passwords - wb: [644] 25 bytes
2021-08-13 17:07:07,062 - helpers.py[DEBUG]: Running config-set-passwords using lock (<FileLock using file '/var/lib/cloud/instances/i-0d483f9ce23b7fccc/sem/config_set_passwords'>)
2021-08-13 17:07:07,062 - cc_set_passwords.py[DEBUG]: Leaving SSH config 'PasswordAuthentication' unchanged. ssh_pwauth=None
2021-08-13 17:07:07,062 - handlers.py[DEBUG]: finish: modules-config/config-set-passwords: SUCCESS: config-set-passwords ran successfully
2021-08-13 17:07:07,063 - stages.py[DEBUG]: Running module grub-dpkg (<module 'cloudinit.config.cc_grub_dpkg' from '/usr/lib/python3/dist-packages/cloudinit/config/cc_grub_dpkg.py'>) with frequency once-per-instance
2021-08-13 17:07:07,063 - handlers.py[DEBUG]: start: modules-config/config-grub-dpkg: running config-grub-dpkg with frequency once-per-instance
2021-08-13 17:07:07,063 - util.py[DEBUG]: Writing to /var/lib/cloud/instances/i-0d483f9ce23b7fccc/sem/config_grub_dpkg - wb: [644] 25 bytes
2021-08-13 17:07:07,063 - helpers.py[DEBUG]: Running config-grub-dpkg using lock (<FileLock using file '/var/lib/cloud/instances/i-0d483f9ce23b7fccc/sem/config_grub_dpkg'>)
2021-08-13 17:07:07,063 - subp.py[DEBUG]: Running command ['grub-probe', '-t', 'disk', '/boot'] with allowed return codes [0] (shell=False, capture=True)
2021-08-13 17:07:07,081 - subp.py[DEBUG]: Running command ['udevadm', 'info', '--root', '--query=symlink', '/dev/xvda'] with allowed return codes [0] (shell=False, capture=True)
2021-08-13 17:07:07,084 - cc_grub_dpkg.py[DEBUG]: considering these device symlinks: 
2021-08-13 17:07:07,084 - cc_grub_dpkg.py[DEBUG]: filtered to these disk/by-id symlinks: 
2021-08-13 17:07:07,084 - cc_grub_dpkg.py[DEBUG]: selected /dev/xvda
2021-08-13 17:07:07,085 - cc_grub_dpkg.py[DEBUG]: Setting grub debconf-set-selections with '/dev/xvda','false'
2021-08-13 17:07:07,085 - subp.py[DEBUG]: Running command ['debconf-set-selections'] with allowed return codes [0] (shell=False, capture=True)
2021-08-13 17:07:07,520 - handlers.py[DEBUG]: finish: modules-config/config-grub-dpkg: SUCCESS: config-grub-dpkg ran successfully
2021-08-13 17:07:07,520 - stages.py[DEBUG]: Running module apt-pipelining (<module 'cloudinit.config.cc_apt_pipelining' from '/usr/lib/python3/dist-packages/cloudinit/config/cc_apt_pipelining.py'>) with frequency once-per-instance
2021-08-13 17:07:07,520 - handlers.py[DEBUG]: start: modules-config/config-apt-pipelining: running config-apt-pipelining with frequency once-per-instance
2021-08-13 17:07:07,520 - util.py[DEBUG]: Writing to /var/lib/cloud/instances/i-0d483f9ce23b7fccc/sem/config_apt_pipelining - wb: [644] 25 bytes
2021-08-13 17:07:07,521 - helpers.py[DEBUG]: Running config-apt-pipelining using lock (<FileLock using file '/var/lib/cloud/instances/i-0d483f9ce23b7fccc/sem/config_apt_pipelining'>)
2021-08-13 17:07:07,521 - handlers.py[DEBUG]: finish: modules-config/config-apt-pipelining: SUCCESS: config-apt-pipelining ran successfully
2021-08-13 17:07:07,521 - stages.py[DEBUG]: Running module apt-configure (<module 'cloudinit.config.cc_apt_configure' from '/usr/lib/python3/dist-packages/cloudinit/config/cc_apt_configure.py'>) with frequency once-per-instance
2021-08-13 17:07:07,521 - handlers.py[DEBUG]: start: modules-config/config-apt-configure: running config-apt-configure with frequency once-per-instance
2021-08-13 17:07:07,522 - util.py[DEBUG]: Writing to /var/lib/cloud/instances/i-0d483f9ce23b7fccc/sem/config_apt_configure - wb: [644] 25 bytes
2021-08-13 17:07:07,522 - helpers.py[DEBUG]: Running config-apt-configure using lock (<FileLock using file '/var/lib/cloud/instances/i-0d483f9ce23b7fccc/sem/config_apt_configure'>)
2021-08-13 17:07:07,523 - cc_apt_configure.py[DEBUG]: debconf_selections was not set in config
2021-08-13 17:07:07,523 - util.py[DEBUG]: Reading from /etc/os-release (quiet=True)
2021-08-13 17:07:07,523 - util.py[DEBUG]: Read 382 bytes from /etc/os-release
2021-08-13 17:07:07,523 - util.py[DEBUG]: Reading from /etc/system-image/channel.ini (quiet=True)
2021-08-13 17:07:07,523 - util.py[DEBUG]: Read 0 bytes from /etc/system-image/channel.ini
2021-08-13 17:07:07,523 - cc_apt_configure.py[DEBUG]: handling apt config: {}
2021-08-13 17:07:07,524 - subp.py[DEBUG]: Running command ['lsb_release', '--all'] with allowed return codes [0] (shell=False, capture=True)
2021-08-13 17:07:07,586 - subp.py[DEBUG]: Running command ['dpkg', '--print-architecture'] with allowed return codes [0] (shell=False, capture=True)
2021-08-13 17:07:07,590 - cc_apt_configure.py[DEBUG]: got primary mirror: None
2021-08-13 17:07:07,590 - cc_apt_configure.py[DEBUG]: got security mirror: None
2021-08-13 17:07:07,590 - subp.py[DEBUG]: Running command ['dpkg', '--print-architecture'] with allowed return codes [0] (shell=False, capture=True)
2021-08-13 17:07:07,594 - util.py[DEBUG]: search for mirror in candidates: '['http://us-east-1.ec2.archive.ubuntu.com/ubuntu/', 'http://us-east-1a.clouds.archive.ubuntu.com/ubuntu/', 'http://us-east-1.clouds.archive.ubuntu.com/ubuntu/']'
2021-08-13 17:07:07,613 - util.py[DEBUG]: Resolving URL: http://us-east-1.ec2.archive.ubuntu.com/ubuntu/ took 0.018 seconds
2021-08-13 17:07:07,613 - util.py[DEBUG]: found working mirror: 'http://us-east-1.ec2.archive.ubuntu.com/ubuntu/'
2021-08-13 17:07:07,613 - util.py[DEBUG]: search for mirror in candidates: '[]'
2021-08-13 17:07:07,613 - __init__.py[DEBUG]: filtered distro mirror info: {'primary': 'http://us-east-1.ec2.archive.ubuntu.com/ubuntu/', 'security': 'http://security.ubuntu.com/ubuntu'}
2021-08-13 17:07:07,613 - cc_apt_configure.py[DEBUG]: Apt Mirror info: {'primary': 'http://us-east-1.ec2.archive.ubuntu.com/ubuntu/', 'security': 'http://security.ubuntu.com/ubuntu', 'PRIMARY': 'http://us-east-1.ec2.archive.ubuntu.com/ubuntu/', 'SECURITY': 'http://security.ubuntu.com/ubuntu', 'MIRROR': 'http://us-east-1.ec2.archive.ubuntu.com/ubuntu/'}
2021-08-13 17:07:07,613 - cc_apt_configure.py[INFO]: No custom template provided, fall back to builtin
2021-08-13 17:07:07,614 - util.py[DEBUG]: Reading from /etc/cloud/templates/sources.list.ubuntu.tmpl (quiet=False)
2021-08-13 17:07:07,614 - util.py[DEBUG]: Read 2858 bytes from /etc/cloud/templates/sources.list.ubuntu.tmpl
2021-08-13 17:07:07,621 - util.py[DEBUG]: Writing to /etc/apt/sources.list - wb: [644] 3330 bytes
2021-08-13 17:07:07,624 - cc_apt_configure.py[DEBUG]: Renaming apt list /var/lib/apt/lists/archive.ubuntu.com_ubuntu_dists_focal_restricted_i18n_Translation-en to /var/lib/apt/lists/us-east-1.ec2.archive.ubuntu.com_ubuntu_dists_focal_restricted_i18n_Translation-en
2021-08-13 17:07:07,626 - cc_apt_configure.py[DEBUG]: Renaming apt list /var/lib/apt/lists/archive.ubuntu.com_ubuntu_dists_focal_InRelease to /var/lib/apt/lists/us-east-1.ec2.archive.ubuntu.com_ubuntu_dists_focal_InRelease
2021-08-13 17:07:07,629 - cc_apt_configure.py[DEBUG]: Renaming apt list /var/lib/apt/lists/archive.ubuntu.com_ubuntu_dists_focal-updates_main_i18n_Translation-en to /var/lib/apt/lists/us-east-1.ec2.archive.ubuntu.com_ubuntu_dists_focal-updates_main_i18n_Translation-en
2021-08-13 17:07:07,630 - cc_apt_configure.py[DEBUG]: Renaming apt list /var/lib/apt/lists/archive.ubuntu.com_ubuntu_dists_focal-updates_InRelease to /var/lib/apt/lists/us-east-1.ec2.archive.ubuntu.com_ubuntu_dists_focal-updates_InRelease
2021-08-13 17:07:07,630 - cc_apt_configure.py[DEBUG]: Renaming apt list /var/lib/apt/lists/archive.ubuntu.com_ubuntu_dists_focal_restricted_binary-amd64_Packages to /var/lib/apt/lists/us-east-1.ec2.archive.ubuntu.com_ubuntu_dists_focal_restricted_binary-amd64_Packages
2021-08-13 17:07:07,630 - cc_apt_configure.py[DEBUG]: Renaming apt list /var/lib/apt/lists/archive.ubuntu.com_ubuntu_dists_focal_main_binary-amd64_Packages to /var/lib/apt/lists/us-east-1.ec2.archive.ubuntu.com_ubuntu_dists_focal_main_binary-amd64_Packages
2021-08-13 17:07:07,630 - cc_apt_configure.py[DEBUG]: Renaming apt list /var/lib/apt/lists/archive.ubuntu.com_ubuntu_dists_focal_main_i18n_Translation-en to /var/lib/apt/lists/us-east-1.ec2.archive.ubuntu.com_ubuntu_dists_focal_main_i18n_Translation-en
2021-08-13 17:07:07,630 - cc_apt_configure.py[DEBUG]: Renaming apt list /var/lib/apt/lists/archive.ubuntu.com_ubuntu_dists_focal-updates_restricted_i18n_Translation-en to /var/lib/apt/lists/us-east-1.ec2.archive.ubuntu.com_ubuntu_dists_focal-updates_restricted_i18n_Translation-en
2021-08-13 17:07:07,630 - cc_apt_configure.py[DEBUG]: Renaming apt list /var/lib/apt/lists/archive.ubuntu.com_ubuntu_dists_focal-updates_main_cnf_Commands-amd64 to /var/lib/apt/lists/us-east-1.ec2.archive.ubuntu.com_ubuntu_dists_focal-updates_main_cnf_Commands-amd64
2021-08-13 17:07:07,630 - cc_apt_configure.py[DEBUG]: Renaming apt list /var/lib/apt/lists/archive.ubuntu.com_ubuntu_dists_focal-updates_restricted_cnf_Commands-amd64 to /var/lib/apt/lists/us-east-1.ec2.archive.ubuntu.com_ubuntu_dists_focal-updates_restricted_cnf_Commands-amd64
2021-08-13 17:07:07,630 - cc_apt_configure.py[DEBUG]: Renaming apt list /var/lib/apt/lists/archive.ubuntu.com_ubuntu_dists_focal-updates_restricted_binary-amd64_Packages to /var/lib/apt/lists/us-east-1.ec2.archive.ubuntu.com_ubuntu_dists_focal-updates_restricted_binary-amd64_Packages
2021-08-13 17:07:07,630 - cc_apt_configure.py[DEBUG]: Renaming apt list /var/lib/apt/lists/archive.ubuntu.com_ubuntu_dists_focal_main_cnf_Commands-amd64 to /var/lib/apt/lists/us-east-1.ec2.archive.ubuntu.com_ubuntu_dists_focal_main_cnf_Commands-amd64
2021-08-13 17:07:07,630 - cc_apt_configure.py[DEBUG]: Renaming apt list /var/lib/apt/lists/archive.ubuntu.com_ubuntu_dists_focal_restricted_cnf_Commands-amd64 to /var/lib/apt/lists/us-east-1.ec2.archive.ubuntu.com_ubuntu_dists_focal_restricted_cnf_Commands-amd64
2021-08-13 17:07:07,630 - cc_apt_configure.py[DEBUG]: Renaming apt list /var/lib/apt/lists/archive.ubuntu.com_ubuntu_dists_focal-updates_main_binary-amd64_Packages to /var/lib/apt/lists/us-east-1.ec2.archive.ubuntu.com_ubuntu_dists_focal-updates_main_binary-amd64_Packages
2021-08-13 17:07:07,630 - handlers.py[DEBUG]: finish: modules-config/config-apt-configure: SUCCESS: config-apt-configure ran successfully
2021-08-13 17:07:07,630 - stages.py[DEBUG]: Running module ubuntu-advantage (<module 'cloudinit.config.cc_ubuntu_advantage' from '/usr/lib/python3/dist-packages/cloudinit/config/cc_ubuntu_advantage.py'>) with frequency once-per-instance
2021-08-13 17:07:07,631 - handlers.py[DEBUG]: start: modules-config/config-ubuntu-advantage: running config-ubuntu-advantage with frequency once-per-instance
2021-08-13 17:07:07,631 - util.py[DEBUG]: Writing to /var/lib/cloud/instances/i-0d483f9ce23b7fccc/sem/config_ubuntu_advantage - wb: [644] 24 bytes
2021-08-13 17:07:07,631 - helpers.py[DEBUG]: Running config-ubuntu-advantage using lock (<FileLock using file '/var/lib/cloud/instances/i-0d483f9ce23b7fccc/sem/config_ubuntu_advantage'>)
2021-08-13 17:07:07,631 - cc_ubuntu_advantage.py[DEBUG]: Skipping module named ubuntu-advantage, no 'ubuntu_advantage' configuration found
2021-08-13 17:07:07,631 - handlers.py[DEBUG]: finish: modules-config/config-ubuntu-advantage: SUCCESS: config-ubuntu-advantage ran successfully
2021-08-13 17:07:07,631 - stages.py[DEBUG]: Running module ntp (<module 'cloudinit.config.cc_ntp' from '/usr/lib/python3/dist-packages/cloudinit/config/cc_ntp.py'>) with frequency once-per-instance
2021-08-13 17:07:07,632 - handlers.py[DEBUG]: start: modules-config/config-ntp: running config-ntp with frequency once-per-instance
2021-08-13 17:07:07,632 - util.py[DEBUG]: Writing to /var/lib/cloud/instances/i-0d483f9ce23b7fccc/sem/config_ntp - wb: [644] 25 bytes
2021-08-13 17:07:07,632 - helpers.py[DEBUG]: Running config-ntp using lock (<FileLock using file '/var/lib/cloud/instances/i-0d483f9ce23b7fccc/sem/config_ntp'>)
2021-08-13 17:07:07,632 - cc_ntp.py[DEBUG]: Skipping module named ntp, not present or disabled by cfg
2021-08-13 17:07:07,632 - handlers.py[DEBUG]: finish: modules-config/config-ntp: SUCCESS: config-ntp ran successfully
2021-08-13 17:07:07,632 - stages.py[DEBUG]: Running module timezone (<module 'cloudinit.config.cc_timezone' from '/usr/lib/python3/dist-packages/cloudinit/config/cc_timezone.py'>) with frequency once-per-instance
2021-08-13 17:07:07,632 - handlers.py[DEBUG]: start: modules-config/config-timezone: running config-timezone with frequency once-per-instance
2021-08-13 17:07:07,633 - util.py[DEBUG]: Writing to /var/lib/cloud/instances/i-0d483f9ce23b7fccc/sem/config_timezone - wb: [644] 25 bytes
2021-08-13 17:07:07,633 - helpers.py[DEBUG]: Running config-timezone using lock (<FileLock using file '/var/lib/cloud/instances/i-0d483f9ce23b7fccc/sem/config_timezone'>)
2021-08-13 17:07:07,633 - cc_timezone.py[DEBUG]: Skipping module named timezone, no 'timezone' specified
2021-08-13 17:07:07,633 - handlers.py[DEBUG]: finish: modules-config/config-timezone: SUCCESS: config-timezone ran successfully
2021-08-13 17:07:07,633 - stages.py[DEBUG]: Running module disable-ec2-metadata (<module 'cloudinit.config.cc_disable_ec2_metadata' from '/usr/lib/python3/dist-packages/cloudinit/config/cc_disable_ec2_metadata.py'>) with frequency always
2021-08-13 17:07:07,633 - handlers.py[DEBUG]: start: modules-config/config-disable-ec2-metadata: running config-disable-ec2-metadata with frequency always
2021-08-13 17:07:07,633 - helpers.py[DEBUG]: Running config-disable-ec2-metadata using lock (<cloudinit.helpers.DummyLock object at 0x7f8b054ac190>)
2021-08-13 17:07:07,634 - cc_disable_ec2_metadata.py[DEBUG]: Skipping module named disable-ec2-metadata, disabling the ec2 route not enabled
2021-08-13 17:07:07,634 - handlers.py[DEBUG]: finish: modules-config/config-disable-ec2-metadata: SUCCESS: config-disable-ec2-metadata ran successfully
2021-08-13 17:07:07,634 - stages.py[DEBUG]: Running module runcmd (<module 'cloudinit.config.cc_runcmd' from '/usr/lib/python3/dist-packages/cloudinit/config/cc_runcmd.py'>) with frequency once-per-instance
2021-08-13 17:07:07,634 - handlers.py[DEBUG]: start: modules-config/config-runcmd: running config-runcmd with frequency once-per-instance
2021-08-13 17:07:07,634 - util.py[DEBUG]: Writing to /var/lib/cloud/instances/i-0d483f9ce23b7fccc/sem/config_runcmd - wb: [644] 25 bytes
2021-08-13 17:07:07,635 - helpers.py[DEBUG]: Running config-runcmd using lock (<FileLock using file '/var/lib/cloud/instances/i-0d483f9ce23b7fccc/sem/config_runcmd'>)
2021-08-13 17:07:07,635 - cc_runcmd.py[DEBUG]: Skipping module named runcmd, no 'runcmd' key in configuration
2021-08-13 17:07:07,635 - handlers.py[DEBUG]: finish: modules-config/config-runcmd: SUCCESS: config-runcmd ran successfully
2021-08-13 17:07:07,635 - stages.py[DEBUG]: Running module byobu (<module 'cloudinit.config.cc_byobu' from '/usr/lib/python3/dist-packages/cloudinit/config/cc_byobu.py'>) with frequency once-per-instance
2021-08-13 17:07:07,635 - handlers.py[DEBUG]: start: modules-config/config-byobu: running config-byobu with frequency once-per-instance
2021-08-13 17:07:07,635 - util.py[DEBUG]: Writing to /var/lib/cloud/instances/i-0d483f9ce23b7fccc/sem/config_byobu - wb: [644] 24 bytes
2021-08-13 17:07:07,635 - helpers.py[DEBUG]: Running config-byobu using lock (<FileLock using file '/var/lib/cloud/instances/i-0d483f9ce23b7fccc/sem/config_byobu'>)
2021-08-13 17:07:07,636 - cc_byobu.py[DEBUG]: Skipping module named byobu, no 'byobu' values found
2021-08-13 17:07:07,636 - handlers.py[DEBUG]: finish: modules-config/config-byobu: SUCCESS: config-byobu ran successfully
2021-08-13 17:07:07,636 - main.py[DEBUG]: Ran 14 modules with 0 failures
2021-08-13 17:07:07,636 - atomic_helper.py[DEBUG]: Atomically writing to file /var/lib/cloud/data/status.json (via temporary file /var/lib/cloud/data/tmp9r9_we_a) - w: [644] 545 bytes/chars
2021-08-13 17:07:07,636 - util.py[DEBUG]: Reading from /proc/uptime (quiet=False)
2021-08-13 17:07:07,636 - util.py[DEBUG]: Read 11 bytes from /proc/uptime
2021-08-13 17:07:07,637 - util.py[DEBUG]: cloud-init mode 'modules' took 0.779 seconds (0.78)
2021-08-13 17:07:07,637 - handlers.py[DEBUG]: finish: modules-config: SUCCESS: running modules for config
2021-08-13 17:07:08,329 - util.py[DEBUG]: Cloud-init v. 21.1-19-gbad84ad4-0ubuntu1~20.04.2 running 'modules:final' at Fri, 13 Aug 2021 17:07:08 +0000. Up 23.49 seconds.
2021-08-13 17:07:08,359 - stages.py[DEBUG]: Using distro class <class 'cloudinit.distros.ubuntu.Distro'>
2021-08-13 17:07:08,360 - stages.py[DEBUG]: Running module package-update-upgrade-install (<module 'cloudinit.config.cc_package_update_upgrade_install' from '/usr/lib/python3/dist-packages/cloudinit/config/cc_package_update_upgrade_install.py'>) with frequency once-per-instance
2021-08-13 17:07:08,360 - handlers.py[DEBUG]: start: modules-final/config-package-update-upgrade-install: running config-package-update-upgrade-install with frequency once-per-instance
2021-08-13 17:07:08,360 - util.py[DEBUG]: Writing to /var/lib/cloud/instances/i-0d483f9ce23b7fccc/sem/config_package_update_upgrade_install - wb: [644] 24 bytes
2021-08-13 17:07:08,361 - helpers.py[DEBUG]: Running config-package-update-upgrade-install using lock (<FileLock using file '/var/lib/cloud/instances/i-0d483f9ce23b7fccc/sem/config_package_update_upgrade_install'>)
2021-08-13 17:07:08,361 - handlers.py[DEBUG]: finish: modules-final/config-package-update-upgrade-install: SUCCESS: config-package-update-upgrade-install ran successfully
2021-08-13 17:07:08,361 - stages.py[DEBUG]: Running module fan (<module 'cloudinit.config.cc_fan' from '/usr/lib/python3/dist-packages/cloudinit/config/cc_fan.py'>) with frequency once-per-instance
2021-08-13 17:07:08,361 - handlers.py[DEBUG]: start: modules-final/config-fan: running config-fan with frequency once-per-instance
2021-08-13 17:07:08,361 - util.py[DEBUG]: Writing to /var/lib/cloud/instances/i-0d483f9ce23b7fccc/sem/config_fan - wb: [644] 24 bytes
2021-08-13 17:07:08,362 - helpers.py[DEBUG]: Running config-fan using lock (<FileLock using file '/var/lib/cloud/instances/i-0d483f9ce23b7fccc/sem/config_fan'>)
2021-08-13 17:07:08,362 - cc_fan.py[DEBUG]: fan: no 'fan' config entry. disabling
2021-08-13 17:07:08,362 - handlers.py[DEBUG]: finish: modules-final/config-fan: SUCCESS: config-fan ran successfully
2021-08-13 17:07:08,362 - stages.py[DEBUG]: Running module landscape (<module 'cloudinit.config.cc_landscape' from '/usr/lib/python3/dist-packages/cloudinit/config/cc_landscape.py'>) with frequency once-per-instance
2021-08-13 17:07:08,362 - handlers.py[DEBUG]: start: modules-final/config-landscape: running config-landscape with frequency once-per-instance
2021-08-13 17:07:08,362 - util.py[DEBUG]: Writing to /var/lib/cloud/instances/i-0d483f9ce23b7fccc/sem/config_landscape - wb: [644] 25 bytes
2021-08-13 17:07:08,363 - helpers.py[DEBUG]: Running config-landscape using lock (<FileLock using file '/var/lib/cloud/instances/i-0d483f9ce23b7fccc/sem/config_landscape'>)
2021-08-13 17:07:08,363 - handlers.py[DEBUG]: finish: modules-final/config-landscape: SUCCESS: config-landscape ran successfully
2021-08-13 17:07:08,363 - stages.py[DEBUG]: Running module lxd (<module 'cloudinit.config.cc_lxd' from '/usr/lib/python3/dist-packages/cloudinit/config/cc_lxd.py'>) with frequency once-per-instance
2021-08-13 17:07:08,363 - handlers.py[DEBUG]: start: modules-final/config-lxd: running config-lxd with frequency once-per-instance
2021-08-13 17:07:08,363 - util.py[DEBUG]: Writing to /var/lib/cloud/instances/i-0d483f9ce23b7fccc/sem/config_lxd - wb: [644] 25 bytes
2021-08-13 17:07:08,363 - helpers.py[DEBUG]: Running config-lxd using lock (<FileLock using file '/var/lib/cloud/instances/i-0d483f9ce23b7fccc/sem/config_lxd'>)
2021-08-13 17:07:08,363 - cc_lxd.py[DEBUG]: Skipping module named lxd, not present or disabled by cfg
2021-08-13 17:07:08,363 - handlers.py[DEBUG]: finish: modules-final/config-lxd: SUCCESS: config-lxd ran successfully
2021-08-13 17:07:08,364 - stages.py[DEBUG]: Running module ubuntu-drivers (<module 'cloudinit.config.cc_ubuntu_drivers' from '/usr/lib/python3/dist-packages/cloudinit/config/cc_ubuntu_drivers.py'>) with frequency once-per-instance
2021-08-13 17:07:08,364 - handlers.py[DEBUG]: start: modules-final/config-ubuntu-drivers: running config-ubuntu-drivers with frequency once-per-instance
2021-08-13 17:07:08,364 - util.py[DEBUG]: Writing to /var/lib/cloud/instances/i-0d483f9ce23b7fccc/sem/config_ubuntu_drivers - wb: [644] 25 bytes
2021-08-13 17:07:08,364 - helpers.py[DEBUG]: Running config-ubuntu-drivers using lock (<FileLock using file '/var/lib/cloud/instances/i-0d483f9ce23b7fccc/sem/config_ubuntu_drivers'>)
2021-08-13 17:07:08,364 - cc_ubuntu_drivers.py[DEBUG]: Skipping module named ubuntu-drivers, no 'drivers' key in config
2021-08-13 17:07:08,364 - handlers.py[DEBUG]: finish: modules-final/config-ubuntu-drivers: SUCCESS: config-ubuntu-drivers ran successfully
2021-08-13 17:07:08,364 - stages.py[DEBUG]: Running module puppet (<module 'cloudinit.config.cc_puppet' from '/usr/lib/python3/dist-packages/cloudinit/config/cc_puppet.py'>) with frequency once-per-instance
2021-08-13 17:07:08,364 - handlers.py[DEBUG]: start: modules-final/config-puppet: running config-puppet with frequency once-per-instance
2021-08-13 17:07:08,365 - util.py[DEBUG]: Writing to /var/lib/cloud/instances/i-0d483f9ce23b7fccc/sem/config_puppet - wb: [644] 25 bytes
2021-08-13 17:07:08,365 - helpers.py[DEBUG]: Running config-puppet using lock (<FileLock using file '/var/lib/cloud/instances/i-0d483f9ce23b7fccc/sem/config_puppet'>)
2021-08-13 17:07:08,365 - cc_puppet.py[DEBUG]: Skipping module named puppet, no 'puppet' configuration found
2021-08-13 17:07:08,365 - handlers.py[DEBUG]: finish: modules-final/config-puppet: SUCCESS: config-puppet ran successfully
2021-08-13 17:07:08,365 - stages.py[DEBUG]: Running module chef (<module 'cloudinit.config.cc_chef' from '/usr/lib/python3/dist-packages/cloudinit/config/cc_chef.py'>) with frequency always
2021-08-13 17:07:08,365 - handlers.py[DEBUG]: start: modules-final/config-chef: running config-chef with frequency always
2021-08-13 17:07:08,365 - helpers.py[DEBUG]: Running config-chef using lock (<cloudinit.helpers.DummyLock object at 0x7f1a0323d4f0>)
2021-08-13 17:07:08,365 - cc_chef.py[DEBUG]: Skipping module named chef, no 'chef' key in configuration
2021-08-13 17:07:08,365 - handlers.py[DEBUG]: finish: modules-final/config-chef: SUCCESS: config-chef ran successfully
2021-08-13 17:07:08,366 - stages.py[DEBUG]: Running module mcollective (<module 'cloudinit.config.cc_mcollective' from '/usr/lib/python3/dist-packages/cloudinit/config/cc_mcollective.py'>) with frequency once-per-instance
2021-08-13 17:07:08,366 - handlers.py[DEBUG]: start: modules-final/config-mcollective: running config-mcollective with frequency once-per-instance
2021-08-13 17:07:08,366 - util.py[DEBUG]: Writing to /var/lib/cloud/instances/i-0d483f9ce23b7fccc/sem/config_mcollective - wb: [644] 24 bytes
2021-08-13 17:07:08,366 - helpers.py[DEBUG]: Running config-mcollective using lock (<FileLock using file '/var/lib/cloud/instances/i-0d483f9ce23b7fccc/sem/config_mcollective'>)
2021-08-13 17:07:08,366 - cc_mcollective.py[DEBUG]: Skipping module named mcollective, no 'mcollective' key in configuration
2021-08-13 17:07:08,366 - handlers.py[DEBUG]: finish: modules-final/config-mcollective: SUCCESS: config-mcollective ran successfully
2021-08-13 17:07:08,366 - stages.py[DEBUG]: Running module salt-minion (<module 'cloudinit.config.cc_salt_minion' from '/usr/lib/python3/dist-packages/cloudinit/config/cc_salt_minion.py'>) with frequency once-per-instance
2021-08-13 17:07:08,366 - handlers.py[DEBUG]: start: modules-final/config-salt-minion: running config-salt-minion with frequency once-per-instance
2021-08-13 17:07:08,367 - util.py[DEBUG]: Writing to /var/lib/cloud/instances/i-0d483f9ce23b7fccc/sem/config_salt_minion - wb: [644] 25 bytes
2021-08-13 17:07:08,367 - helpers.py[DEBUG]: Running config-salt-minion using lock (<FileLock using file '/var/lib/cloud/instances/i-0d483f9ce23b7fccc/sem/config_salt_minion'>)
2021-08-13 17:07:08,367 - cc_salt_minion.py[DEBUG]: Skipping module named salt-minion, no 'salt_minion' key in configuration
2021-08-13 17:07:08,367 - handlers.py[DEBUG]: finish: modules-final/config-salt-minion: SUCCESS: config-salt-minion ran successfully
2021-08-13 17:07:08,367 - stages.py[DEBUG]: Running module reset_rmc (<module 'cloudinit.config.cc_reset_rmc' from '/usr/lib/python3/dist-packages/cloudinit/config/cc_reset_rmc.py'>) with frequency once-per-instance
2021-08-13 17:07:08,367 - handlers.py[DEBUG]: start: modules-final/config-reset_rmc: running config-reset_rmc with frequency once-per-instance
2021-08-13 17:07:08,367 - util.py[DEBUG]: Writing to /var/lib/cloud/instances/i-0d483f9ce23b7fccc/sem/config_reset_rmc - wb: [644] 25 bytes
2021-08-13 17:07:08,368 - helpers.py[DEBUG]: Running config-reset_rmc using lock (<FileLock using file '/var/lib/cloud/instances/i-0d483f9ce23b7fccc/sem/config_reset_rmc'>)
2021-08-13 17:07:08,368 - cc_reset_rmc.py[DEBUG]: module disabled, RSCT_PATH not present
2021-08-13 17:07:08,369 - handlers.py[DEBUG]: finish: modules-final/config-reset_rmc: SUCCESS: config-reset_rmc ran successfully
2021-08-13 17:07:08,369 - stages.py[DEBUG]: Running module refresh_rmc_and_interface (<module 'cloudinit.config.cc_refresh_rmc_and_interface' from '/usr/lib/python3/dist-packages/cloudinit/config/cc_refresh_rmc_and_interface.py'>) with frequency always
2021-08-13 17:07:08,369 - handlers.py[DEBUG]: start: modules-final/config-refresh_rmc_and_interface: running config-refresh_rmc_and_interface with frequency always
2021-08-13 17:07:08,369 - helpers.py[DEBUG]: Running config-refresh_rmc_and_interface using lock (<cloudinit.helpers.DummyLock object at 0x7f1a0323d4f0>)
2021-08-13 17:07:08,369 - cc_refresh_rmc_and_interface.py[DEBUG]: No 'rmcctrl' in path, disabled
2021-08-13 17:07:08,369 - handlers.py[DEBUG]: finish: modules-final/config-refresh_rmc_and_interface: SUCCESS: config-refresh_rmc_and_interface ran successfully
2021-08-13 17:07:08,369 - stages.py[DEBUG]: Running module rightscale_userdata (<module 'cloudinit.config.cc_rightscale_userdata' from '/usr/lib/python3/dist-packages/cloudinit/config/cc_rightscale_userdata.py'>) with frequency once-per-instance
2021-08-13 17:07:08,369 - handlers.py[DEBUG]: start: modules-final/config-rightscale_userdata: running config-rightscale_userdata with frequency once-per-instance
2021-08-13 17:07:08,370 - util.py[DEBUG]: Writing to /var/lib/cloud/instances/i-0d483f9ce23b7fccc/sem/config_rightscale_userdata - wb: [644] 25 bytes
2021-08-13 17:07:08,370 - helpers.py[DEBUG]: Running config-rightscale_userdata using lock (<FileLock using file '/var/lib/cloud/instances/i-0d483f9ce23b7fccc/sem/config_rightscale_userdata'>)
2021-08-13 17:07:08,370 - cc_rightscale_userdata.py[DEBUG]: Failed to get raw userdata in module rightscale_userdata
2021-08-13 17:07:08,370 - handlers.py[DEBUG]: finish: modules-final/config-rightscale_userdata: SUCCESS: config-rightscale_userdata ran successfully
2021-08-13 17:07:08,370 - stages.py[DEBUG]: Running module scripts-vendor (<module 'cloudinit.config.cc_scripts_vendor' from '/usr/lib/python3/dist-packages/cloudinit/config/cc_scripts_vendor.py'>) with frequency once-per-instance
2021-08-13 17:07:08,370 - handlers.py[DEBUG]: start: modules-final/config-scripts-vendor: running config-scripts-vendor with frequency once-per-instance
2021-08-13 17:07:08,370 - util.py[DEBUG]: Writing to /var/lib/cloud/instances/i-0d483f9ce23b7fccc/sem/config_scripts_vendor - wb: [644] 25 bytes
2021-08-13 17:07:08,372 - helpers.py[DEBUG]: Running config-scripts-vendor using lock (<FileLock using file '/var/lib/cloud/instances/i-0d483f9ce23b7fccc/sem/config_scripts_vendor'>)
2021-08-13 17:07:08,372 - handlers.py[DEBUG]: finish: modules-final/config-scripts-vendor: SUCCESS: config-scripts-vendor ran successfully
2021-08-13 17:07:08,372 - stages.py[DEBUG]: Running module scripts-per-once (<module 'cloudinit.config.cc_scripts_per_once' from '/usr/lib/python3/dist-packages/cloudinit/config/cc_scripts_per_once.py'>) with frequency once
2021-08-13 17:07:08,372 - handlers.py[DEBUG]: start: modules-final/config-scripts-per-once: running config-scripts-per-once with frequency once
2021-08-13 17:07:08,372 - util.py[DEBUG]: Writing to /var/lib/cloud/sem/config_scripts_per_once.once - wb: [644] 25 bytes
2021-08-13 17:07:08,372 - helpers.py[DEBUG]: Running config-scripts-per-once using lock (<FileLock using file '/var/lib/cloud/sem/config_scripts_per_once.once'>)
2021-08-13 17:07:08,373 - handlers.py[DEBUG]: finish: modules-final/config-scripts-per-once: SUCCESS: config-scripts-per-once ran successfully
2021-08-13 17:07:08,373 - stages.py[DEBUG]: Running module scripts-per-boot (<module 'cloudinit.config.cc_scripts_per_boot' from '/usr/lib/python3/dist-packages/cloudinit/config/cc_scripts_per_boot.py'>) with frequency always
2021-08-13 17:07:08,373 - handlers.py[DEBUG]: start: modules-final/config-scripts-per-boot: running config-scripts-per-boot with frequency always
2021-08-13 17:07:08,373 - helpers.py[DEBUG]: Running config-scripts-per-boot using lock (<cloudinit.helpers.DummyLock object at 0x7f1a0323da90>)
2021-08-13 17:07:08,373 - handlers.py[DEBUG]: finish: modules-final/config-scripts-per-boot: SUCCESS: config-scripts-per-boot ran successfully
2021-08-13 17:07:08,373 - stages.py[DEBUG]: Running module scripts-per-instance (<module 'cloudinit.config.cc_scripts_per_instance' from '/usr/lib/python3/dist-packages/cloudinit/config/cc_scripts_per_instance.py'>) with frequency once-per-instance
2021-08-13 17:07:08,373 - handlers.py[DEBUG]: start: modules-final/config-scripts-per-instance: running config-scripts-per-instance with frequency once-per-instance
2021-08-13 17:07:08,373 - util.py[DEBUG]: Writing to /var/lib/cloud/instances/i-0d483f9ce23b7fccc/sem/config_scripts_per_instance - wb: [644] 24 bytes
2021-08-13 17:07:08,374 - helpers.py[DEBUG]: Running config-scripts-per-instance using lock (<FileLock using file '/var/lib/cloud/instances/i-0d483f9ce23b7fccc/sem/config_scripts_per_instance'>)
2021-08-13 17:07:08,374 - handlers.py[DEBUG]: finish: modules-final/config-scripts-per-instance: SUCCESS: config-scripts-per-instance ran successfully
2021-08-13 17:07:08,374 - stages.py[DEBUG]: Running module scripts-user (<module 'cloudinit.config.cc_scripts_user' from '/usr/lib/python3/dist-packages/cloudinit/config/cc_scripts_user.py'>) with frequency once-per-instance
2021-08-13 17:07:08,374 - handlers.py[DEBUG]: start: modules-final/config-scripts-user: running config-scripts-user with frequency once-per-instance
2021-08-13 17:07:08,374 - util.py[DEBUG]: Writing to /var/lib/cloud/instances/i-0d483f9ce23b7fccc/sem/config_scripts_user - wb: [644] 25 bytes
2021-08-13 17:07:08,374 - helpers.py[DEBUG]: Running config-scripts-user using lock (<FileLock using file '/var/lib/cloud/instances/i-0d483f9ce23b7fccc/sem/config_scripts_user'>)
2021-08-13 17:07:08,375 - handlers.py[DEBUG]: finish: modules-final/config-scripts-user: SUCCESS: config-scripts-user ran successfully
2021-08-13 17:07:08,375 - stages.py[DEBUG]: Running module ssh-authkey-fingerprints (<module 'cloudinit.config.cc_ssh_authkey_fingerprints' from '/usr/lib/python3/dist-packages/cloudinit/config/cc_ssh_authkey_fingerprints.py'>) with frequency once-per-instance
2021-08-13 17:07:08,375 - handlers.py[DEBUG]: start: modules-final/config-ssh-authkey-fingerprints: running config-ssh-authkey-fingerprints with frequency once-per-instance
2021-08-13 17:07:08,375 - util.py[DEBUG]: Writing to /var/lib/cloud/instances/i-0d483f9ce23b7fccc/sem/config_ssh_authkey_fingerprints - wb: [644] 25 bytes
2021-08-13 17:07:08,375 - helpers.py[DEBUG]: Running config-ssh-authkey-fingerprints using lock (<FileLock using file '/var/lib/cloud/instances/i-0d483f9ce23b7fccc/sem/config_ssh_authkey_fingerprints'>)
2021-08-13 17:07:08,376 - util.py[DEBUG]: Reading from /etc/ssh/sshd_config (quiet=False)
2021-08-13 17:07:08,376 - util.py[DEBUG]: Read 3287 bytes from /etc/ssh/sshd_config
2021-08-13 17:07:08,376 - util.py[DEBUG]: Reading from /home/ubuntu/.ssh/authorized_keys (quiet=False)
2021-08-13 17:07:08,376 - util.py[DEBUG]: Read 388 bytes from /home/ubuntu/.ssh/authorized_keys
2021-08-13 17:07:08,431 - handlers.py[DEBUG]: finish: modules-final/config-ssh-authkey-fingerprints: SUCCESS: config-ssh-authkey-fingerprints ran successfully
2021-08-13 17:07:08,431 - stages.py[DEBUG]: Running module keys-to-console (<module 'cloudinit.config.cc_keys_to_console' from '/usr/lib/python3/dist-packages/cloudinit/config/cc_keys_to_console.py'>) with frequency once-per-instance
2021-08-13 17:07:08,432 - handlers.py[DEBUG]: start: modules-final/config-keys-to-console: running config-keys-to-console with frequency once-per-instance
2021-08-13 17:07:08,432 - util.py[DEBUG]: Writing to /var/lib/cloud/instances/i-0d483f9ce23b7fccc/sem/config_keys_to_console - wb: [644] 25 bytes
2021-08-13 17:07:08,432 - helpers.py[DEBUG]: Running config-keys-to-console using lock (<FileLock using file '/var/lib/cloud/instances/i-0d483f9ce23b7fccc/sem/config_keys_to_console'>)
2021-08-13 17:07:08,432 - subp.py[DEBUG]: Running command ['/usr/lib/cloud-init/write-ssh-key-fingerprints', '', 'ssh-dss'] with allowed return codes [0] (shell=False, capture=True)
2021-08-13 17:07:08,554 - handlers.py[DEBUG]: finish: modules-final/config-keys-to-console: SUCCESS: config-keys-to-console ran successfully
2021-08-13 17:07:08,554 - stages.py[DEBUG]: Running module phone-home (<module 'cloudinit.config.cc_phone_home' from '/usr/lib/python3/dist-packages/cloudinit/config/cc_phone_home.py'>) with frequency once-per-instance
2021-08-13 17:07:08,555 - handlers.py[DEBUG]: start: modules-final/config-phone-home: running config-phone-home with frequency once-per-instance
2021-08-13 17:07:08,555 - util.py[DEBUG]: Writing to /var/lib/cloud/instances/i-0d483f9ce23b7fccc/sem/config_phone_home - wb: [644] 25 bytes
2021-08-13 17:07:08,555 - helpers.py[DEBUG]: Running config-phone-home using lock (<FileLock using file '/var/lib/cloud/instances/i-0d483f9ce23b7fccc/sem/config_phone_home'>)
2021-08-13 17:07:08,556 - cc_phone_home.py[DEBUG]: Skipping module named phone-home, no 'phone_home' configuration found
2021-08-13 17:07:08,556 - handlers.py[DEBUG]: finish: modules-final/config-phone-home: SUCCESS: config-phone-home ran successfully
2021-08-13 17:07:08,556 - stages.py[DEBUG]: Running module final-message (<module 'cloudinit.config.cc_final_message' from '/usr/lib/python3/dist-packages/cloudinit/config/cc_final_message.py'>) with frequency always
2021-08-13 17:07:08,556 - handlers.py[DEBUG]: start: modules-final/config-final-message: running config-final-message with frequency always
2021-08-13 17:07:08,556 - helpers.py[DEBUG]: Running config-final-message using lock (<cloudinit.helpers.DummyLock object at 0x7f1a0323da90>)
2021-08-13 17:07:08,556 - util.py[DEBUG]: Reading from /proc/uptime (quiet=False)
2021-08-13 17:07:08,556 - util.py[DEBUG]: Read 11 bytes from /proc/uptime
2021-08-13 17:07:08,559 - util.py[DEBUG]: Cloud-init v. 21.1-19-gbad84ad4-0ubuntu1~20.04.2 finished at Fri, 13 Aug 2021 17:07:08 +0000. Datasource DataSourceEc2Local.  Up 23.78 seconds
2021-08-13 17:07:08,559 - util.py[DEBUG]: Writing to /var/lib/cloud/instance/boot-finished - wb: [644] 80 bytes
2021-08-13 17:07:08,560 - handlers.py[DEBUG]: finish: modules-final/config-final-message: SUCCESS: config-final-message ran successfully
2021-08-13 17:07:08,560 - stages.py[DEBUG]: Running module power-state-change (<module 'cloudinit.config.cc_power_state_change' from '/usr/lib/python3/dist-packages/cloudinit/config/cc_power_state_change.py'>) with frequency once-per-instance
2021-08-13 17:07:08,560 - handlers.py[DEBUG]: start: modules-final/config-power-state-change: running config-power-state-change with frequency once-per-instance
2021-08-13 17:07:08,560 - util.py[DEBUG]: Writing to /var/lib/cloud/instances/i-0d483f9ce23b7fccc/sem/config_power_state_change - wb: [644] 24 bytes
2021-08-13 17:07:08,561 - helpers.py[DEBUG]: Running config-power-state-change using lock (<FileLock using file '/var/lib/cloud/instances/i-0d483f9ce23b7fccc/sem/config_power_state_change'>)
2021-08-13 17:07:08,561 - cc_power_state_change.py[DEBUG]: no power_state provided. doing nothing
2021-08-13 17:07:08,561 - handlers.py[DEBUG]: finish: modules-final/config-power-state-change: SUCCESS: config-power-state-change ran successfully
2021-08-13 17:07:08,561 - main.py[DEBUG]: Ran 22 modules with 0 failures
2021-08-13 17:07:08,561 - atomic_helper.py[DEBUG]: Atomically writing to file /var/lib/cloud/data/status.json (via temporary file /var/lib/cloud/data/tmp8yn011q_) - w: [644] 572 bytes/chars
2021-08-13 17:07:08,562 - atomic_helper.py[DEBUG]: Atomically writing to file /var/lib/cloud/data/result.json (via temporary file /var/lib/cloud/data/tmprdghohep) - w: [644] 69 bytes/chars
2021-08-13 17:07:08,562 - util.py[DEBUG]: Creating symbolic link from '/run/cloud-init/result.json' => '../../var/lib/cloud/data/result.json'
2021-08-13 17:07:08,562 - util.py[DEBUG]: Reading from /proc/uptime (quiet=False)
2021-08-13 17:07:08,562 - util.py[DEBUG]: Read 11 bytes from /proc/uptime
2021-08-13 17:07:08,562 - util.py[DEBUG]: cloud-init mode 'modules' took 0.302 seconds (0.30)
2021-08-13 17:07:08,562 - handlers.py[DEBUG]: finish: modules-final: SUCCESS: running modules for final
